<?xml version="1.0" encoding="utf-8"?>
<!-- This URDF was automatically created by SolidWorks to URDF Exporter! Originally created by Stephen Brawner (brawner@gmail.com) 
     Commit Version: 1.6.0-4-g7f85cfe  Build Version: 1.6.7995.38578
     For more information, please see http://wiki.ros.org/sw_urdf_exporter -->
<robot
  name="rohand_left">
  <link
    name="base_link">
    <inertial>
      <origin
        xyz="-0.0545705623202243 0.000958522654081762 -0.00306438373173582"
        rpy="0 0 0" />
      <mass
        value="0.0367658161456593" />
      <inertia
        ixx="1.4186714203091E-05"
        ixy="2.20190989146005E-06"
        ixz="5.69534967571968E-07"
        iyy="1.58584689691376E-05"
        iyz="1.24561852404914E-07"
        izz="2.47326344757226E-05" />
    </inertial>
    <visual>
      <origin
        xyz="0 0 0"
        rpy="0 0 0" />
      <geometry>
        <mesh
          filename="package://rohand_lites_urdf_ros2/meshes_l/base_link.STL" />
      </geometry>
      <material
        name="">
        <color
          rgba="1 1 1 1" />
      </material>
    </visual>
    <collision>
      <origin
        xyz="0 0 0"
        rpy="0 0 0" />
      <geometry>
        <mesh
          filename="package://rohand_lites_urdf_ros2/meshes_l/base_link.STL" />
      </geometry>
    </collision>
  </link>
  <link
    name="if_slider_link">
    <inertial>
      <origin
        xyz="-0.0124609302264191 5.72373766036249E-07 -5.10403661765912E-07"
        rpy="0 0 0" />
      <mass
        value="0.000366976779244888" />
      <inertia
        ixx="2.29234196925927E-09"
        ixy="3.24469272752374E-13"
        ixz="3.38787799495353E-12"
        iyy="2.2656719155403E-08"
        iyz="3.65015309503903E-11"
        izz="2.30714121797335E-08" />
    </inertial>
    <visual>
      <origin
        xyz="0 0 0"
        rpy="0 0 0" />
      <geometry>
        <mesh
          filename="package://rohand_lites_urdf_ros2/meshes_l/if_slider_link.STL" />
      </geometry>
      <material
        name="">
        <color
          rgba="1 1 1 1" />
      </material>
    </visual>
    <collision>
      <origin
        xyz="0 0 0"
        rpy="0 0 0" />
      <geometry>
        <mesh
          filename="package://rohand_lites_urdf_ros2/meshes_l/if_slider_link.STL" />
      </geometry>
    </collision>
  </link>
  <joint
    name="if_slider_link"
    type="prismatic">
    <origin
      xyz="-0.069843 0.025413 -0.0095469"
      rpy="0.00048469 -0.0046058 -0.10485" />
    <parent
      link="base_link" />
    <child
      link="if_slider_link" />
    <axis
      xyz="1 0 0" />
    <limit
      lower="-0.003"
      upper="0.016"
      effort="0"
      velocity="0" />
  </joint>
  <link
    name="if_slider_abpart_link">
    <inertial>
      <origin
        xyz="-0.00866996321770879 -0.00290002109580619 -0.00099880462815537"
        rpy="0 0 0" />
      <mass
        value="0.000320776967954908" />
      <inertia
        ixx="1.20513143090749E-09"
        ixy="-1.68388029459414E-15"
        ixz="-5.98294194501094E-10"
        iyy="3.82102698793214E-09"
        iyz="-7.44774967271784E-15"
        izz="4.09509407772891E-09" />
    </inertial>
    <visual>
      <origin
        xyz="0 0 0"
        rpy="0 0 0" />
      <geometry>
        <mesh
          filename="package://rohand_lites_urdf_ros2/meshes_l/if_slider_abpart_link.STL" />
      </geometry>
      <material
        name="">
        <color
          rgba="1 1 1 1" />
      </material>
    </visual>
    <collision>
      <origin
        xyz="0 0 0"
        rpy="0 0 0" />
      <geometry>
        <mesh
          filename="package://rohand_lites_urdf_ros2/meshes_l/if_slider_abpart_link.STL" />
      </geometry>
    </collision>
  </link>
  <joint
    name="if_slider_abpart_link"
    type="continuous">
    <origin
      xyz="-0.026698 0.0028818 -0.00025213"
      rpy="-0.087268 -0.0045707 -0.00023228" />
    <parent
      link="if_slider_link" />
    <child
      link="if_slider_abpart_link" />
    <axis
      xyz="0 1 0" />
  </joint>
  <link
    name="if_proximal_link">
    <inertial>
      <origin
        xyz="-0.01442568349862 0.00682000254611658 0.0074253497626635"
        rpy="0 0 0" />
      <mass
        value="0.0020519557292877" />
      <inertia
        ixx="8.09627570327931E-08"
        ixy="4.81487284472085E-12"
        ixz="2.82088862566871E-08"
        iyy="1.89814037862563E-07"
        iyz="-4.52934896397488E-12"
        izz="1.96626325307393E-07" />
    </inertial>
    <visual>
      <origin
        xyz="0 0 0"
        rpy="0 0 0" />
      <geometry>
        <mesh
          filename="package://rohand_lites_urdf_ros2/meshes_l/if_proximal_link.STL" />
      </geometry>
      <material
        name="">
        <color
          rgba="1 1 1 1" />
      </material>
    </visual>
    <collision>
      <origin
        xyz="0 0 0"
        rpy="0 0 0" />
      <geometry>
        <mesh
          filename="package://rohand_lites_urdf_ros2/meshes_l/if_proximal_link.STL" />
      </geometry>
    </collision>
  </link>
  <joint
    name="if_proximal_link"
    type="continuous">
    <origin
      xyz="-0.10628 0.036856 -0.0014156"
      rpy="3.0548 -0.0091764 -0.10508" />
    <parent
      link="base_link" />
    <child
      link="if_proximal_link" />
    <axis
      xyz="0 -1 0" />
  </joint>
  <link
    name="if_distal_link">
    <inertial>
      <origin
        xyz="-0.0123180967294782 -0.00644820912302179 -0.0158568630315067"
        rpy="0 0 0" />
      <mass
        value="0.00375858037616174" />
      <inertia
        ixx="2.63130516542119E-07"
        ixy="-2.88831462706391E-10"
        ixz="-1.76316850016938E-07"
        iyy="4.17185892023749E-07"
        iyz="-3.2422000909467E-10"
        izz="2.11620474724111E-07" />
    </inertial>
    <visual>
      <origin
        xyz="0 0 0"
        rpy="0 0 0" />
      <geometry>
        <mesh
          filename="package://rohand_lites_urdf_ros2/meshes_l/if_distal_link.STL" />
      </geometry>
      <material
        name="">
        <color
          rgba="1 1 1 1" />
      </material>
    </visual>
    <collision>
      <origin
        xyz="0 0 0"
        rpy="0 0 0" />
      <geometry>
        <mesh
          filename="package://rohand_lites_urdf_ros2/meshes_l/if_distal_link.STL" />
      </geometry>
    </collision>
  </link>
  <joint
    name="if_distal_link"
    type="continuous">
    <origin
      xyz="-0.030939 0.00036803 0.010438"
      rpy="3.1416 0 0" />
    <parent
      link="if_proximal_link" />
    <child
      link="if_distal_link" />
    <axis
      xyz="0 1 0" />
  </joint>
  <link
    name="if_connecting_link">
    <inertial>
      <origin
        xyz="-0.0102937748382793 0.00326999998406902 0.0115190490734171"
        rpy="0 0 0" />
      <mass
        value="0.000166924672312448" />
      <inertia
        ixx="9.75202938767627E-09"
        ixy="1.75066519666902E-16"
        ixz="9.61783960160431E-09"
        iyy="1.97461626872891E-08"
        iyz="-4.14592995796692E-16"
        izz="1.00119386293862E-08" />
    </inertial>
    <visual>
      <origin
        xyz="0 0 0"
        rpy="0 0 0" />
      <geometry>
        <mesh
          filename="package://rohand_lites_urdf_ros2/meshes_l/if_connecting_link.STL" />
      </geometry>
      <material
        name="">
        <color
          rgba="1 1 1 1" />
      </material>
    </visual>
    <collision>
      <origin
        xyz="0 0 0"
        rpy="0 0 0" />
      <geometry>
        <mesh
          filename="package://rohand_lites_urdf_ros2/meshes_l/if_connecting_link.STL" />
      </geometry>
    </collision>
  </link>
  <joint
    name="if_connecting_link"
    type="continuous">
    <origin
      xyz="-0.11349 0.034413 0.0028462"
      rpy="3.0548 -0.0091764 -0.10508" />
    <parent
      link="base_link" />
    <child
      link="if_connecting_link" />
    <axis
      xyz="0 -1 0" />
  </joint>
  <link
    name="mf_slider_link">
    <inertial>
      <origin
        xyz="-0.0124609290610269 -6.11772286714801E-07 4.5281338316612E-07"
        rpy="0 0 0" />
      <mass
        value="0.000366976877786862" />
      <inertia
        ixx="2.29234276983421E-09"
        ixy="-3.49229091915779E-14"
        ixz="-3.37681626061809E-12"
        iyy="2.26535312378929E-08"
        iyz="-2.55563390623366E-14"
        izz="2.30746004253858E-08" />
    </inertial>
    <visual>
      <origin
        xyz="0 0 0"
        rpy="0 0 0" />
      <geometry>
        <mesh
          filename="package://rohand_lites_urdf_ros2/meshes_l/mf_slider_link.STL" />
      </geometry>
      <material
        name="">
        <color
          rgba="1 1 1 1" />
      </material>
    </visual>
    <collision>
      <origin
        xyz="0 0 0"
        rpy="0 0 0" />
      <geometry>
        <mesh
          filename="package://rohand_lites_urdf_ros2/meshes_l/mf_slider_link.STL" />
      </geometry>
    </collision>
  </link>
  <joint
    name="mf_slider_link"
    type="prismatic">
    <origin
      xyz="-0.072667 0.010715 -0.0056801"
      rpy="0.00016779 -0.0046649 -0.035953" />
    <parent
      link="base_link" />
    <child
      link="mf_slider_link" />
    <axis
      xyz="1 0 0" />
    <limit
      lower="-0.003"
      upper="0.016"
      effort="0"
      velocity="0" />
  </joint>
  <link
    name="mf_slider_abpart_link">
    <inertial>
      <origin
        xyz="-0.00863166147672864 -0.00290002109561248 -0.00128852359058317"
        rpy="0 0 0" />
      <mass
        value="0.000320776968205779" />
      <inertia
        ixx="1.24841151711596E-09"
        ixy="-1.43339719165473E-15"
        ixz="-6.93657416532179E-10"
        iyy="3.82102698950838E-09"
        iyz="-7.50051871661411E-15"
        izz="4.05181399621468E-09" />
    </inertial>
    <visual>
      <origin
        xyz="0 0 0"
        rpy="0 0 0" />
      <geometry>
        <mesh
          filename="package://rohand_lites_urdf_ros2/meshes_l/mf_slider_abpart_link.STL" />
      </geometry>
      <material
        name="">
        <color
          rgba="1 1 1 1" />
      </material>
    </visual>
    <collision>
      <origin
        xyz="0 0 0"
        rpy="0 0 0" />
      <geometry>
        <mesh
          filename="package://rohand_lites_urdf_ros2/meshes_l/mf_slider_abpart_link.STL" />
      </geometry>
    </collision>
  </link>
  <joint
    name="mf_slider_abpart_link"
    type="continuous">
    <origin
      xyz="-0.026701 0.0028167 0"
      rpy="0 0.0046708 0.00026078" />
    <parent
      link="mf_slider_link" />
    <child
      link="mf_slider_abpart_link" />
    <axis
      xyz="0 1 0" />
  </joint>
  <link
    name="mf_proximal_link">
    <inertial>
      <origin
        xyz="-0.0163278718217205 -0.00649192295378876 -0.00963335617479526"
        rpy="0 0 0" />
      <mass
        value="0.00248819746655502" />
      <inertia
        ixx="1.10601992595461E-07"
        ixy="4.54446489000609E-11"
        ixz="-6.04962189304454E-08"
        iyy="2.84385954136736E-07"
        iyz="4.48881092592545E-11"
        izz="2.73053329475105E-07" />
    </inertial>
    <visual>
      <origin
        xyz="0 0 0"
        rpy="0 0 0" />
      <geometry>
        <mesh
          filename="package://rohand_lites_urdf_ros2/meshes_l/mf_proximal_link.STL" />
      </geometry>
      <material
        name="">
        <color
          rgba="1 1 1 1" />
      </material>
    </visual>
    <collision>
      <origin
        xyz="0 0 0"
        rpy="0 0 0" />
      <geometry>
        <mesh
          filename="package://rohand_lites_urdf_ros2/meshes_l/mf_proximal_link.STL" />
      </geometry>
    </collision>
  </link>
  <joint
    name="mf_proximal_link"
    type="continuous">
    <origin
      xyz="-0.11015 0.018475 0.0030758"
      rpy="0.00016503 0 -0.035692" />
    <parent
      link="base_link" />
    <child
      link="mf_proximal_link" />
    <axis
      xyz="0 1 0" />
  </joint>
  <link
    name="mf_distal_link">
    <inertial>
      <origin
        xyz="-0.0117763908650274 -0.00644267727147304 -0.0162627454095642"
        rpy="0 0 0" />
      <mass
        value="0.00375852857432825" />
      <inertia
        ixx="2.74945310213643E-07"
        ixy="-2.76421249981728E-10"
        ixz="-1.74176296887232E-07"
        iyy="4.17175733749449E-07"
        iyz="-3.32560853157935E-10"
        izz="1.99795426402673E-07" />
    </inertial>
    <visual>
      <origin
        xyz="0 0 0"
        rpy="0 0 0" />
      <geometry>
        <mesh
          filename="package://rohand_lites_urdf_ros2/meshes_l/mf_distal_link.STL" />
      </geometry>
      <material
        name="">
        <color
          rgba="1 1 1 1" />
      </material>
    </visual>
    <collision>
      <origin
        xyz="0 0 0"
        rpy="0 0 0" />
      <geometry>
        <mesh
          filename="package://rohand_lites_urdf_ros2/meshes_l/mf_distal_link.STL" />
      </geometry>
    </collision>
  </link>
  <joint
    name="mf_distal_link"
    type="continuous">
    <origin
      xyz="-0.034844 -5.0349E-05 -0.013726"
      rpy="0.0043984 0.00019026 -0.0075363" />
    <parent
      link="mf_proximal_link" />
    <child
      link="mf_distal_link" />
    <axis
      xyz="0 1 0" />
  </joint>
  <link
    name="mf_connecting_link">
    <inertial>
      <origin
        xyz="-0.0118628475192756 -0.00294999987872081 -0.0130516664950286"
        rpy="0 0 0" />
      <mass
        value="0.000182842940071169" />
      <inertia
        ixx="1.36687582797894E-08"
        ixy="-1.44099062766258E-16"
        ixz="-1.38287310284971E-08"
        iyy="2.82058742732517E-08"
        iyz="-1.11717461849029E-16"
        izz="1.45566192948587E-08" />
    </inertial>
    <visual>
      <origin
        xyz="0 0 0"
        rpy="0 0 0" />
      <geometry>
        <mesh
          filename="package://rohand_lites_urdf_ros2/meshes_l/mf_connecting_link.STL" />
      </geometry>
      <material
        name="">
        <color
          rgba="1 1 1 1" />
      </material>
    </visual>
    <collision>
      <origin
        xyz="0 0 0"
        rpy="0 0 0" />
      <geometry>
        <mesh
          filename="package://rohand_lites_urdf_ros2/meshes_l/mf_connecting_link.STL" />
      </geometry>
    </collision>
  </link>
  <joint
    name="mf_connecting_link"
    type="continuous">
    <origin
      xyz="-0.11719 0.015178 0.0070447"
      rpy="0.00016503 0 -0.035692" />
    <parent
      link="base_link" />
    <child
      link="mf_connecting_link" />
    <axis
      xyz="0 1 0" />
  </joint>
  <link
    name="rf_slider_link">
    <inertial>
      <origin
        xyz="-0.012460930626961 6.14830955047302E-07 -4.58590170952095E-07"
        rpy="0 0 0" />
      <mass
        value="0.0003669767565826" />
      <inertia
        ixx="2.29234191400953E-09"
        ixy="2.68131759401659E-14"
        ixz="3.40328324616147E-12"
        iyy="2.26535300110567E-08"
        iyz="-1.79312577249578E-14"
        izz="2.30745994328123E-08" />
    </inertial>
    <visual>
      <origin
        xyz="0 0 0"
        rpy="0 0 0" />
      <geometry>
        <mesh
          filename="package://rohand_lites_urdf_ros2/meshes_l/rf_slider_link.STL" />
      </geometry>
      <material
        name="">
        <color
          rgba="1 1 1 1" />
      </material>
    </visual>
    <collision>
      <origin
        xyz="0 0 0"
        rpy="0 0 0" />
      <geometry>
        <mesh
          filename="package://rohand_lites_urdf_ros2/meshes_l/rf_slider_link.STL" />
      </geometry>
    </collision>
  </link>
  <joint
    name="rf_slider_link"
    type="prismatic">
    <origin
      xyz="-0.070868 -0.0049857 -0.0063498"
      rpy="-0.00016399 -0.0047127 0.034784" />
    <parent
      link="base_link" />
    <child
      link="rf_slider_link" />
    <axis
      xyz="1 0 0" />
    <limit
      lower="-0.003"
      upper="0.016"
      effort="0"
      velocity="0" />
  </joint>
  <link
    name="rf_slider_abpart_link">
    <inertial>
      <origin
        xyz="-0.00866034407178994 -0.00290002110643861 -0.0010790335475469"
        rpy="0 0 0" />
      <mass
        value="0.000320776968158487" />
      <inertia
        ixx="1.21645742906764E-09"
        ixy="-1.59611659562264E-15"
        ixz="-6.24947489612752E-10"
        iyy="3.82102699927636E-09"
        iyz="-7.46030305603E-15"
        izz="4.08376810315974E-09" />
    </inertial>
    <visual>
      <origin
        xyz="0 0 0"
        rpy="0 0 0" />
      <geometry>
        <mesh
          filename="package://rohand_lites_urdf_ros2/meshes_l/rf_slider_abpart_link.STL" />
      </geometry>
      <material
        name="">
        <color
          rgba="1 1 1 1" />
      </material>
    </visual>
    <collision>
      <origin
        xyz="0 0 0"
        rpy="0 0 0" />
      <geometry>
        <mesh
          filename="package://rohand_lites_urdf_ros2/meshes_l/rf_slider_abpart_link.STL" />
      </geometry>
    </collision>
  </link>
  <joint
    name="rf_slider_abpart_link"
    type="continuous">
    <origin
      xyz="-0.026698 0.0028938 0"
      rpy="0 0.0047182 -0.00063032" />
    <parent
      link="rf_slider_link" />
    <child
      link="rf_slider_abpart_link" />
    <axis
      xyz="0 1 0" />
  </joint>
  <link
    name="rf_proximal_link">
    <inertial>
      <origin
        xyz="-0.0143563671796693 0.00681998649341342 0.00755846536702151"
        rpy="0 0 0" />
      <mass
        value="0.00205195671379772" />
      <inertia
        ixx="8.14944652395064E-08"
        ixy="4.70955665732311E-12"
        ixz="2.92740657063271E-08"
        iyy="1.89813738079667E-07"
        iyz="-4.49039618473885E-12"
        izz="1.96094351731653E-07" />
    </inertial>
    <visual>
      <origin
        xyz="0 0 0"
        rpy="0 0 0" />
      <geometry>
        <mesh
          filename="package://rohand_lites_urdf_ros2/meshes_l/rf_proximal_link.STL" />
      </geometry>
      <material
        name="">
        <color
          rgba="1 1 1 1" />
      </material>
    </visual>
    <collision>
      <origin
        xyz="0 0 0"
        rpy="0 0 0" />
      <geometry>
        <mesh
          filename="package://rohand_lites_urdf_ros2/meshes_l/rf_proximal_link.STL" />
      </geometry>
    </collision>
  </link>
  <joint
    name="rf_proximal_link"
    type="continuous">
    <origin
      xyz="-0.10852 0.00052975 0.0024009"
      rpy="3.1414 0 0.034153" />
    <parent
      link="base_link" />
    <child
      link="rf_proximal_link" />
    <axis
      xyz="0 -1 0" />
  </joint>
  <link
    name="rf_distal_link">
    <inertial>
      <origin
        xyz="-0.0121730609739191 -0.00644820716902625 -0.0159684309110027"
        rpy="0 0 0" />
      <mass
        value="0.00375858491630908" />
      <inertia
        ixx="2.66337255501028E-07"
        ixy="-2.83461617317305E-10"
        ixz="-1.75817185730185E-07"
        iyy="4.1718477440461E-07"
        iyz="-3.26281131146206E-10"
        izz="2.08412424444304E-07" />
    </inertial>
    <visual>
      <origin
        xyz="0 0 0"
        rpy="0 0 0" />
      <geometry>
        <mesh
          filename="package://rohand_lites_urdf_ros2/meshes_l/rf_distal_link.STL" />
      </geometry>
      <material
        name="">
        <color
          rgba="1 1 1 1" />
      </material>
    </visual>
    <collision>
      <origin
        xyz="0 0 0"
        rpy="0 0 0" />
      <geometry>
        <mesh
          filename="package://rohand_lites_urdf_ros2/meshes_l/rf_distal_link.STL" />
      </geometry>
    </collision>
  </link>
  <joint
    name="rf_distal_link"
    type="continuous">
    <origin
      xyz="-0.030791 0.00036828 0.010696"
      rpy="-3.1374 0.00011174 0.0076423" />
    <parent
      link="rf_proximal_link" />
    <child
      link="rf_distal_link" />
    <axis
      xyz="0 1 0" />
  </joint>
  <link
    name="rf_connecting_link">
    <inertial>
      <origin
        xyz="-0.0101867819636627 0.00326999999371734 0.0116137650891053"
        rpy="0 0 0" />
      <mass
        value="0.000166924666599283" />
      <inertia
        ixx="9.92995680244984E-09"
        ixy="1.70851142887045E-16"
        ixz="9.61859762618002E-09"
        iyy="1.97461620340103E-08"
        iyz="-4.15726940419676E-16"
        izz="9.83401056082882E-09" />
    </inertial>
    <visual>
      <origin
        xyz="0 0 0"
        rpy="0 0 0" />
      <geometry>
        <mesh
          filename="package://rohand_lites_urdf_ros2/meshes_l/rf_connecting_link.STL" />
      </geometry>
      <material
        name="">
        <color
          rgba="1 1 1 1" />
      </material>
    </visual>
    <collision>
      <origin
        xyz="0 0 0"
        rpy="0 0 0" />
      <geometry>
        <mesh
          filename="package://rohand_lites_urdf_ros2/meshes_l/rf_connecting_link.STL" />
      </geometry>
    </collision>
  </link>
  <joint
    name="rf_connecting_link"
    type="continuous">
    <origin
      xyz="-0.11531 -0.0032532 0.0063702"
      rpy="3.1414 0 0.034153" />
    <parent
      link="base_link" />
    <child
      link="rf_connecting_link" />
    <axis
      xyz="0 -1 0" />
  </joint>
  <link
    name="lf_slider_link">
    <inertial>
      <origin
        xyz="-0.0125897603100827 -6.60163440580064E-09 5.04727197536692E-09"
        rpy="0 0 0" />
      <mass
        value="0.000362008073494643" />
      <inertia
        ixx="2.27333116746049E-09"
        ixy="5.73998907629929E-15"
        ixz="1.14228065893748E-15"
        iyy="1.67766199370518E-08"
        iyz="-3.6344664974767E-11"
        izz="1.71906061026764E-08" />
    </inertial>
    <visual>
      <origin
        xyz="0 0 0"
        rpy="0 0 0" />
      <geometry>
        <mesh
          filename="package://rohand_lites_urdf_ros2/meshes_l/lf_slider_link.STL" />
      </geometry>
      <material
        name="">
        <color
          rgba="1 1 1 1" />
      </material>
    </visual>
    <collision>
      <origin
        xyz="0 0 0"
        rpy="0 0 0" />
      <geometry>
        <mesh
          filename="package://rohand_lites_urdf_ros2/meshes_l/lf_slider_link.STL" />
      </geometry>
    </collision>
  </link>
  <joint
    name="lf_slider_link"
    type="prismatic">
    <origin
      xyz="-0.067893 -0.020252 -0.0086272"
      rpy="-0.00046288 -0.0047418 0.097308" />
    <parent
      link="base_link" />
    <child
      link="lf_slider_link" />
    <axis
      xyz="1 0 0" />
    <limit
      lower="-0.003"
      upper="0.016"
      effort="0"
      velocity="0" />
  </joint>
  <link
    name="lf_slider_abpart_link">
    <inertial>
      <origin
        xyz="-0.00864364242436283 -0.00290002110515897 -0.00120553661345373"
        rpy="0 0 0" />
      <mass
        value="0.000320776967954136" />
      <inertia
        ixx="1.23534245745788E-09"
        ixy="-1.48852368571339E-15"
        ixz="-6.66597305576038E-10"
        iyy="3.82102698772227E-09"
        iyz="-7.48289393604186E-15"
        izz="4.06488306317346E-09" />
    </inertial>
    <visual>
      <origin
        xyz="0 0 0"
        rpy="0 0 0" />
      <geometry>
        <mesh
          filename="package://rohand_lites_urdf_ros2/meshes_l/lf_slider_abpart_link.STL" />
      </geometry>
      <material
        name="">
        <color
          rgba="1 1 1 1" />
      </material>
    </visual>
    <collision>
      <origin
        xyz="0 0 0"
        rpy="0 0 0" />
      <geometry>
        <mesh
          filename="package://rohand_lites_urdf_ros2/meshes_l/lf_slider_abpart_link.STL" />
      </geometry>
    </collision>
  </link>
  <joint
    name="lf_slider_abpart_link"
    type="continuous">
    <origin
      xyz="-0.026696 0.0029268 0.00025609"
      rpy="0.087275 -0.0036108 -0.0016294" />
    <parent
      link="lf_slider_link" />
    <child
      link="lf_slider_abpart_link" />
    <axis
      xyz="0 1 0" />
  </joint>
  <link
    name="lf_proximal_link">
    <inertial>
      <origin
        xyz="-0.0126783172515542 -0.00650017197922771 -0.00752321049293611"
        rpy="0 0 0" />
      <mass
        value="0.00183703203876047" />
      <inertia
        ixx="7.28737257765291E-08"
        ixy="2.35202799697226E-12"
        ixz="-2.23948893152069E-08"
        iyy="1.40967655054569E-07"
        iyz="-1.69318267527159E-13"
        izz="1.47027755964671E-07" />
    </inertial>
    <visual>
      <origin
        xyz="0 0 0"
        rpy="0 0 0" />
      <geometry>
        <mesh
          filename="package://rohand_lites_urdf_ros2/meshes_l/lf_proximal_link.STL" />
      </geometry>
      <material
        name="">
        <color
          rgba="1 1 1 1" />
      </material>
    </visual>
    <collision>
      <origin
        xyz="0 0 0"
        rpy="0 0 0" />
      <geometry>
        <mesh
          filename="package://rohand_lites_urdf_ros2/meshes_l/lf_proximal_link.STL" />
      </geometry>
    </collision>
  </link>
  <joint
    name="lf_proximal_link"
    type="continuous">
    <origin
      xyz="-0.10588 -0.01818 0.00065724"
      rpy="0.08682 -0.0083534 0.09568" />
    <parent
      link="base_link" />
    <child
      link="lf_proximal_link" />
    <axis
      xyz="0 1 0" />
  </joint>
  <link
    name="lf_distal_link">
    <inertial>
      <origin
        xyz="-0.00651882753544765 -0.00644854835323535 -0.0135103943691352"
        rpy="0 0 0" />
      <mass
        value="0.00243586918410262" />
      <inertia
        ixx="1.19172237830121E-07"
        ixy="-9.23092755649748E-11"
        ixz="-4.29645591151488E-08"
        iyy="1.418248902462E-07"
        iyz="-1.66762811141822E-10"
        izz="5.41634126707913E-08" />
    </inertial>
    <visual>
      <origin
        xyz="0 0 0"
        rpy="0 0 0" />
      <geometry>
        <mesh
          filename="package://rohand_lites_urdf_ros2/meshes_l/lf_distal_link.STL" />
      </geometry>
      <material
        name="">
        <color
          rgba="1 1 1 1" />
      </material>
    </visual>
    <collision>
      <origin
        xyz="0 0 0"
        rpy="0 0 0" />
      <geometry>
        <mesh
          filename="package://rohand_lites_urdf_ros2/meshes_l/lf_distal_link.STL" />
      </geometry>
    </collision>
  </link>
  <joint
    name="lf_distal_link"
    type="continuous">
    <origin
      xyz="-0.026922 -5.0837E-05 -0.010935"
      rpy="0 0 0" />
    <parent
      link="lf_proximal_link" />
    <child
      link="lf_distal_link" />
    <axis
      xyz="0 1 0" />
  </joint>
  <link
    name="lf_connecting_link">
    <inertial>
      <origin
        xyz="-0.00788529910898948 -0.00295000006561827 -0.0114003485805511"
        rpy="0 0 0" />
      <mass
        value="0.000153781965229355" />
      <inertia
        ixx="9.26881021136169E-09"
        ixy="-2.01981787623042E-16"
        ixz="-7.122145599423E-09"
        iyy="1.51199180005882E-08"
        iyz="-1.80045379258162E-16"
        izz="5.86751143325546E-09" />
    </inertial>
    <visual>
      <origin
        xyz="0 0 0"
        rpy="0 0 0" />
      <geometry>
        <mesh
          filename="package://rohand_lites_urdf_ros2/meshes_l/lf_connecting_link.STL" />
      </geometry>
      <material
        name="">
        <color
          rgba="1 1 1 1" />
      </material>
    </visual>
    <collision>
      <origin
        xyz="0 0 0"
        rpy="0 0 0" />
      <geometry>
        <mesh
          filename="package://rohand_lites_urdf_ros2/meshes_l/lf_connecting_link.STL" />
      </geometry>
    </collision>
  </link>
  <joint
    name="lf_connecting_link"
    type="continuous">
    <origin
      xyz="-0.1124 -0.022708 0.0043038"
      rpy="0.08682 -0.0083534 0.09568" />
    <parent
      link="base_link" />
    <child
      link="lf_connecting_link" />
    <axis
      xyz="0 1 0" />
  </joint>
  <link
    name="th_root_link">
    <inertial>
      <origin
        xyz="-0.0191689187756942 0.00569828615821762 -0.0016693852678177"
        rpy="0 0 0" />
      <mass
        value="0.00195345377003282" />
      <inertia
        ixx="1.6596112048292E-07"
        ixy="7.96099037248168E-08"
        ixz="-1.16578799172214E-08"
        iyy="1.8147620690714E-07"
        iyz="1.22841840818757E-08"
        izz="2.16329221955122E-07" />
    </inertial>
    <visual>
      <origin
        xyz="0 0 0"
        rpy="0 0 0" />
      <geometry>
        <mesh
          filename="package://rohand_lites_urdf_ros2/meshes_l/th_root_link.STL" />
      </geometry>
      <material
        name="">
        <color
          rgba="1 1 1 1" />
      </material>
    </visual>
    <collision>
      <origin
        xyz="0 0 0"
        rpy="0 0 0" />
      <geometry>
        <mesh
          filename="package://rohand_lites_urdf_ros2/meshes_l/th_root_link.STL" />
      </geometry>
    </collision>
  </link>
  <joint
    name="th_root_link"
    type="revolute">
    <origin
      xyz="-0.02474 0.01826 -0.019216"
      rpy="0.0075757 -0.22303 -0.034238" />
    <parent
      link="base_link" />
    <child
      link="th_root_link" />
    <axis
      xyz="-1 0 0" />
    <limit
      lower="0"
      upper="1.57"
      effort="0"
      velocity="0" />
  </joint>
  <link
    name="th_proximal_link">
    <inertial>
      <origin
        xyz="-0.0185320909111181 0.00765760336647799 0.00769895948516403"
        rpy="0 0 0" />
      <mass
        value="0.00646398971921865" />
      <inertia
        ixx="5.69701043131816E-07"
        ixy="4.94299712334608E-07"
        ixz="-1.81638866874203E-09"
        iyy="1.67594826700605E-06"
        iyz="5.54953034071743E-10"
        izz="2.12783428410059E-06" />
    </inertial>
    <visual>
      <origin
        xyz="0 0 0"
        rpy="0 0 0" />
      <geometry>
        <mesh
          filename="package://rohand_lites_urdf_ros2/meshes_l/th_proximal_link.STL" />
      </geometry>
      <material
        name="">
        <color
          rgba="1 1 1 1" />
      </material>
    </visual>
    <collision>
      <origin
        xyz="0 0 0"
        rpy="0 0 0" />
      <geometry>
        <mesh
          filename="package://rohand_lites_urdf_ros2/meshes_l/th_proximal_link.STL" />
      </geometry>
    </collision>
  </link>
  <joint
    name="th_proximal_link"
    type="continuous">
    <origin
      xyz="-0.0281675109233723 0.0206776396558676 -0.010414259606288"
      rpy="-0.00721290411178693 0.000240878411888333 0.0333895499404722" />
    <parent
      link="th_root_link" />
    <child
      link="th_proximal_link" />
    <axis
      xyz="0 0 -1" />
  </joint>
  <link
    name="th_slider_link">
    <inertial>
      <origin
        xyz="0.0112452481317033 -0.00126425660582853 -1.09266148232284E-05"
        rpy="0 0 0" />
      <mass
        value="0.000954858111723104" />
      <inertia
        ixx="2.43404692845525E-08"
        ixy="-1.43062349889764E-09"
        ixz="-1.09962428592104E-11"
        iyy="7.82499086975144E-08"
        iyz="1.46816487980795E-10"
        izz="6.03992318614701E-08" />
    </inertial>
    <visual>
      <origin
        xyz="0 0 0"
        rpy="0 0 0" />
      <geometry>
        <mesh
          filename="package://rohand_lites_urdf_ros2/meshes_l/th_slider_link.STL" />
      </geometry>
      <material
        name="">
        <color
          rgba="1 1 1 1" />
      </material>
    </visual>
    <collision>
      <origin
        xyz="0 0 0"
        rpy="0 0 0" />
      <geometry>
        <mesh
          filename="package://rohand_lites_urdf_ros2/meshes_l/th_slider_link.STL" />
      </geometry>
    </collision>
  </link>
  <joint
    name="th_slider_link"
    type="prismatic">
    <origin
      xyz="-0.00693753286125505 0.0060015383018569 0.00770000000000735"
      rpy="3.13340301156162 0 2.64819881385431" />
    <parent
      link="th_proximal_link" />
    <child
      link="th_slider_link" />
    <axis
      xyz="-1 0 0" />
    <limit
      lower="-0.003"
      upper="0.007"
      effort="0"
      velocity="0" />
  </joint>
  <link
    name="th_connecting_link">
    <inertial>
      <origin
        xyz="-0.00407965795015313 0.00107206899501235 0.0041801031784283"
        rpy="0 0 0" />
      <mass
        value="0.000246838976516484" />
      <inertia
        ixx="1.43879636085563E-09"
        ixy="3.47084935433479E-10"
        ixz="4.3475397471377E-14"
        iyy="3.21709337845879E-09"
        iyz="-1.66003052230679E-14"
        izz="2.87385641221495E-09" />
    </inertial>
    <visual>
      <origin
        xyz="0 0 0"
        rpy="0 0 0" />
      <geometry>
        <mesh
          filename="package://rohand_lites_urdf_ros2/meshes_l/th_connecting_link.STL" />
      </geometry>
      <material
        name="">
        <color
          rgba="1 1 1 1" />
      </material>
    </visual>
    <collision>
      <origin
        xyz="0 0 0"
        rpy="0 0 0" />
      <geometry>
        <mesh
          filename="package://rohand_lites_urdf_ros2/meshes_l/th_connecting_link.STL" />
      </geometry>
    </collision>
  </link>
  <joint
    name="th_connecting_link"
    type="continuous">
    <origin
      xyz="0.0342999999310514 9.49029098650939E-05 0.00428598656136089"
      rpy="3.13437975502215 -0.00387873583868189 2.64821280237015" />
    <parent
      link="th_slider_link" />
    <child
      link="th_connecting_link" />
    <axis
      xyz="0 0 -1" />
  </joint>
  <link
    name="th_distal_link">
    <inertial>
      <origin
        xyz="-0.00904754564000706 0.00635260162604825 0.00681129533264973"
        rpy="0 0 0" />
      <mass
        value="0.00464616025042038" />
      <inertia
        ixx="1.73155668678773E-07"
        ixy="2.14376248212519E-08"
        ixz="7.68875433779967E-12"
        iyy="2.35273874670456E-07"
        iyz="-7.75559011609892E-13"
        izz="2.09949102085074E-07" />
    </inertial>
    <visual>
      <origin
        xyz="0 0 0"
        rpy="0 0 0" />
      <geometry>
        <mesh
          filename="package://rohand_lites_urdf_ros2/meshes_l/th_distal_link.STL" />
      </geometry>
      <material
        name="">
        <color
          rgba="1 1 1 1" />
      </material>
    </visual>
    <collision>
      <origin
        xyz="0 0 0"
        rpy="0 0 0" />
      <geometry>
        <mesh
          filename="package://rohand_lites_urdf_ros2/meshes_l/th_distal_link.STL" />
      </geometry>
    </collision>
  </link>
  <joint
    name="th_distal_link"
    type="continuous">
    <origin
      xyz="-0.0479097598406365 0.0140073523016571 0.000879436248969738"
      rpy="0 0 0" />
    <parent
      link="th_proximal_link" />
    <child
      link="th_distal_link" />
    <axis
      xyz="0 0 -1" />
  </joint>
</robot>
