<?xml version="1.0" encoding="utf-8"?>
<!-- This URDF was automatically created by SolidWorks to URDF Exporter! Originally created by Stephen Brawner (brawner@gmail.com) 
     Commit Version: 1.6.0-4-g7f85cfe  Build Version: 1.6.7995.38578
     For more information, please see http://wiki.ros.org/sw_urdf_exporter -->
<robot
  name="rohand_right">
  <link
    name="base_link">
    <inertial>
      <origin
        xyz="-0.0545222815204033 0.00285484521225937 0.000774376071271499"
        rpy="0 0 0" />
      <mass
        value="0.036767125483042" />
      <inertia
        ixx="1.38889790573648E-05"
        ixy="-2.06624701332099E-06"
        ixz="5.59506060369248E-07"
        iyy="1.61548453329456E-05"
        iyz="-1.63276101783862E-07"
        izz="2.47308806982349E-05" />
    </inertial>
    <visual>
      <origin
        xyz="0 0 0"
        rpy="0 0 0" />
      <geometry>
        <mesh
          filename="package://rohand_lites_urdf_ros2/meshes_r/base_link.STL" />
      </geometry>
      <material
        name="">
        <color
          rgba="1 1 1 1" />
      </material>
    </visual>
    <collision>
      <origin
        xyz="0 0 0"
        rpy="0 0 0" />
      <geometry>
        <mesh
          filename="package://rohand_lites_urdf_ros2/meshes_r/base_link.STL" />
      </geometry>
    </collision>
  </link>
  <link
    name="if_slider_link">
    <inertial>
      <origin
        xyz="-0.0124530425745341 -0.000436239822210277 -5.78809522521623E-05"
        rpy="0 0 0" />
      <mass
        value="0.00036698643915296" />
      <inertia
        ixx="2.3176753080737E-09"
        ixy="-7.11675058255555E-10"
        ixz="-9.10432291326428E-11"
        iyy="2.26323784710106E-08"
        iyz="-3.94895501477935E-11"
        izz="2.30714845351554E-08" />
    </inertial>
    <visual>
      <origin
        xyz="0 0 0"
        rpy="0 0 0" />
      <geometry>
        <mesh
          filename="package://rohand_lites_urdf_ros2/meshes_r/if_slider_link.STL" />
      </geometry>
      <material
        name="">
        <color
          rgba="1 1 1 1" />
      </material>
    </visual>
    <collision>
      <origin
        xyz="0 0 0"
        rpy="0 0 0" />
      <geometry>
        <mesh
          filename="package://rohand_lites_urdf_ros2/meshes_r/if_slider_link.STL" />
      </geometry>
    </collision>
  </link>
  <joint
    name="if_slider_link"
    type="prismatic">
    <origin
      xyz="-0.074613 -0.020587 -0.005722"
      rpy="0 0 0" />
    <parent
      link="base_link" />
    <child
      link="if_slider_link" />
    <axis
      xyz="0.99938 0.034963 0.0046058" />
    <limit
      lower="0"
      upper="0.019"
      effort="0"
      velocity="0" />
  </joint>
  <link
    name="if_slider_abpart_link">
    <inertial>
      <origin
        xyz="-0.0092498650934466 -0.000350689750009542 0.00020148547861952"
        rpy="0 0 0" />
      <mass
        value="0.000302366083858827" />
      <inertia
        ixx="1.04387160230758E-09"
        ixy="-8.36268956467088E-11"
        ixz="-1.84540396192816E-10"
        iyy="3.81180163507327E-09"
        iyz="-3.56109814062949E-11"
        izz="4.14450670534174E-09" />
    </inertial>
    <visual>
      <origin
        xyz="0 0 0"
        rpy="0 0 0" />
      <geometry>
        <mesh
          filename="package://rohand_lites_urdf_ros2/meshes_r/if_slider_abpart_link.STL" />
      </geometry>
      <material
        name="">
        <color
          rgba="0.752941176470588 0.752941176470588 0.752941176470588 1" />
      </material>
    </visual>
    <collision>
      <origin
        xyz="0 0 0"
        rpy="0 0 0" />
      <geometry>
        <mesh
          filename="package://rohand_lites_urdf_ros2/meshes_r/if_slider_abpart_link.STL" />
      </geometry>
    </collision>
  </link>
  <joint
    name="if_slider_abpart_link"
    type="continuous">
    <origin
      xyz="-0.026684 -0.00092834 -0.00012252"
      rpy="0 0 0" />
    <parent
      link="if_slider_link" />
    <child
      link="if_slider_abpart_link" />
    <axis
      xyz="0.03586 -0.99559 -0.08667" />
  </joint>
  <link
    name="if_proximal_link">
    <inertial>
      <origin
        xyz="-0.0160094940673838 -0.000349485553492873 -0.00260441299332094"
        rpy="0 0 0" />
      <mass
        value="0.00205196484818472" />
      <inertia
        ixx="7.56275571674263E-08"
        ixy="-5.07338563561986E-09"
        ixz="1.10804593970052E-08"
        iyy="1.89696859852745E-07"
        iyz="-6.66396824862034E-10"
        izz="2.02083394574501E-07" />
    </inertial>
    <visual>
      <origin
        xyz="0 0 0"
        rpy="0 0 0" />
      <geometry>
        <mesh
          filename="package://rohand_lites_urdf_ros2/meshes_r/if_proximal_link.STL" />
      </geometry>
      <material
        name="">
        <color
          rgba="1 1 1 1" />
      </material>
    </visual>
    <collision>
      <origin
        xyz="0 0 0"
        rpy="0 0 0" />
      <geometry>
        <mesh
          filename="package://rohand_lites_urdf_ros2/meshes_r/if_proximal_link.STL" />
      </geometry>
    </collision>
  </link>
  <joint
    name="if_proximal_link"
    type="continuous">
    <origin
      xyz="-0.10885 -0.022559 0.0030149"
      rpy="0 0 0" />
    <parent
      link="base_link" />
    <child
      link="if_proximal_link" />
    <axis
      xyz="0.03586 -0.99559 -0.08667" />
  </joint>
  <link
    name="if_distal_link">
    <inertial>
      <origin
        xyz="-0.0196300817769823 -0.000640491793587189 -0.00436107710764215"
        rpy="0 0 0" />
      <mass
        value="0.00375207700561759" />
      <inertia
        ixx="6.89300054359263E-08"
        ixy="-7.08836639871154E-09"
        ixz="-5.77055497329753E-08"
        iyy="4.17116914523132E-07"
        iyz="-1.03546708341965E-09"
        izz="4.06060234224632E-07" />
    </inertial>
    <visual>
      <origin
        xyz="0 0 0"
        rpy="0 0 0" />
      <geometry>
        <mesh
          filename="package://rohand_lites_urdf_ros2/meshes_r/if_distal_link.STL" />
      </geometry>
      <material
        name="">
        <color
          rgba="1 1 1 1" />
      </material>
    </visual>
    <collision>
      <origin
        xyz="0 0 0"
        rpy="0 0 0" />
      <geometry>
        <mesh
          filename="package://rohand_lites_urdf_ros2/meshes_r/if_distal_link.STL" />
      </geometry>
    </collision>
  </link>
  <joint
    name="if_distal_link"
    type="continuous">
    <origin
      xyz="-0.03264 -0.00084447 -0.00035932"
      rpy="0 0 0" />
    <parent
      link="if_proximal_link" />
    <child
      link="if_distal_link" />
    <axis
      xyz="0.03586 -0.99559 -0.08667" />
  </joint>
  <link
    name="if_connecting_link">
    <inertial>
      <origin
        xyz="-0.0140289421962829 5.77054328253224E-05 -0.00646746520640533"
        rpy="0 0 0" />
      <mass
        value="0.000166925588454653" />
      <inertia
        ixx="2.771002181587E-09"
        ixy="-4.75443387206387E-11"
        ixz="-6.47747290202885E-09"
        iyy="1.97439407931101E-08"
        iyz="6.16691852357721E-12"
        izz="1.69952427183925E-08" />
    </inertial>
    <visual>
      <origin
        xyz="0 0 0"
        rpy="0 0 0" />
      <geometry>
        <mesh
          filename="package://rohand_lites_urdf_ros2/meshes_r/if_connecting_link.STL" />
      </geometry>
      <material
        name="">
        <color
          rgba="1 1 1 1" />
      </material>
    </visual>
    <collision>
      <origin
        xyz="0 0 0"
        rpy="0 0 0" />
      <geometry>
        <mesh
          filename="package://rohand_lites_urdf_ros2/meshes_r/if_connecting_link.STL" />
      </geometry>
    </collision>
  </link>
  <joint
    name="if_connecting_link"
    type="continuous">
    <origin
      xyz="-0.11575 -0.023152 0.006969"
      rpy="0 0 0" />
    <parent
      link="base_link" />
    <child
      link="if_connecting_link" />
    <axis
      xyz="0.03586 -0.99559 -0.08667" />
  </joint>
  <link
    name="mf_slider_link">
    <inertial>
      <origin
        xyz="-0.0124534871299311 0.000423264345140034 -5.76889563803622E-05"
        rpy="0 0 0" />
      <mass
        value="0.000366986670362037" />
      <inertia
        ixx="2.31627272419319E-09"
        ixy="6.90224899029091E-10"
        ixz="-1.00221985466303E-10"
        iyy="2.26307120370605E-08"
        iyz="3.50496146706607E-12"
        izz="2.30745734059245E-08" />
    </inertial>
    <visual>
      <origin
        xyz="0 0 0"
        rpy="0 0 0" />
      <geometry>
        <mesh
          filename="package://rohand_lites_urdf_ros2/meshes_r/mf_slider_link.STL" />
      </geometry>
      <material
        name="">
        <color
          rgba="1 1 1 1" />
      </material>
    </visual>
    <collision>
      <origin
        xyz="0 0 0"
        rpy="0 0 0" />
      <geometry>
        <mesh
          filename="package://rohand_lites_urdf_ros2/meshes_r/mf_slider_link.STL" />
      </geometry>
    </collision>
  </link>
  <joint
    name="mf_slider_link"
    type="prismatic">
    <origin
      xyz="-0.076404 -0.0055105 -0.0018554"
      rpy="0 0 0" />
    <parent
      link="base_link" />
    <child
      link="mf_slider_link" />
    <axis
      xyz="0.99941 -0.033919 0.0046649" />
    <limit
      lower="0"
      upper="0.019"
      effort="0"
      velocity="0" />
  </joint>
  <link
    name="mf_slider_abpart_link">
    <inertial>
      <origin
        xyz="-0.00925251315344511 0.000316446127319014 -0.0001201917721778"
        rpy="0 0 0" />
      <mass
        value="0.000302366084321501" />
      <inertia
        ixx="1.06139421274176E-09"
        ixy="9.40179619696187E-11"
        ixz="-2.93850181956167E-10"
        iyy="3.80850028687833E-09"
        iyz="1.01094040301621E-11"
        izz="4.1302854722785E-09" />
    </inertial>
    <visual>
      <origin
        xyz="0 0 0"
        rpy="0 0 0" />
      <geometry>
        <mesh
          filename="package://rohand_lites_urdf_ros2/meshes_r/mf_slider_abpart_link.STL" />
      </geometry>
      <material
        name="">
        <color
          rgba="0.752941176470588 0.752941176470588 0.752941176470588 1" />
      </material>
    </visual>
    <collision>
      <origin
        xyz="0 0 0"
        rpy="0 0 0" />
      <geometry>
        <mesh
          filename="package://rohand_lites_urdf_ros2/meshes_r/mf_slider_abpart_link.STL" />
      </geometry>
    </collision>
  </link>
  <joint
    name="mf_slider_abpart_link"
    type="continuous">
    <origin
      xyz="-0.026681 0.00098972 -0.00012456"
      rpy="0 0 0" />
    <parent
      link="mf_slider_link" />
    <child
      link="mf_slider_abpart_link" />
    <axis
      xyz="-0.034181 -0.99942 0.00016502" />
  </joint>
  <link
    name="mf_proximal_link">
    <inertial>
      <origin
        xyz="-0.0184903673769418 0.000627861149851361 -0.00413935122659213"
        rpy="0 0 0" />
      <mass
        value="0.00248820352291794" />
      <inertia
        ixx="9.07785379436329E-08"
        ixy="6.55562272210878E-09"
        ixz="-1.44310845531958E-09"
        iyy="2.84225050641897E-07"
        iyz="2.3061839551177E-11"
        izz="2.93151289533576E-07" />
    </inertial>
    <visual>
      <origin
        xyz="0 0 0"
        rpy="0 0 0" />
      <geometry>
        <mesh
          filename="package://rohand_lites_urdf_ros2/meshes_r/mf_proximal_link.STL" />
      </geometry>
      <material
        name="">
        <color
          rgba="1 1 1 1" />
      </material>
    </visual>
    <collision>
      <origin
        xyz="0 0 0"
        rpy="0 0 0" />
      <geometry>
        <mesh
          filename="package://rohand_lites_urdf_ros2/meshes_r/mf_proximal_link.STL" />
      </geometry>
    </collision>
  </link>
  <joint
    name="mf_proximal_link"
    type="continuous">
    <origin
      xyz="-0.11096 -0.0042498 0.0069142"
      rpy="0 0 0" />
    <parent
      link="base_link" />
    <child
      link="mf_proximal_link" />
    <axis
      xyz="-0.034181 -0.99942 0.00016502" />
  </joint>
  <link
    name="mf_distal_link">
    <inertial>
      <origin
        xyz="-0.0193532072971226 0.000182847336466785 -0.00549439170257794"
        rpy="0 0 0" />
      <mass
        value="0.00375206640497232" />
      <inertia
        ixx="7.70611590028156E-08"
        ixy="9.20009840293414E-09"
        ixz="-7.72573426173603E-08"
        iyy="4.1702278209215E-07"
        iyz="2.08725900112901E-09"
        izz="3.98021007000328E-07" />
    </inertial>
    <visual>
      <origin
        xyz="0 0 0"
        rpy="0 0 0" />
      <geometry>
        <mesh
          filename="package://rohand_lites_urdf_ros2/meshes_r/mf_distal_link.STL" />
      </geometry>
      <material
        name="">
        <color
          rgba="1 1 1 1" />
      </material>
    </visual>
    <collision>
      <origin
        xyz="0 0 0"
        rpy="0 0 0" />
      <geometry>
        <mesh
          filename="package://rohand_lites_urdf_ros2/meshes_r/mf_distal_link.STL" />
      </geometry>
    </collision>
  </link>
  <joint
    name="mf_distal_link"
    type="continuous">
    <origin
      xyz="-0.037403 0.0015832 -0.0023459"
      rpy="0 0 0" />
    <parent
      link="mf_proximal_link" />
    <child
      link="mf_distal_link" />
    <axis
      xyz="-0.025542 -0.99967 -0.0010432" />
  </joint>
  <link
    name="mf_connecting_link">
    <inertial>
      <origin
        xyz="-0.0159081961564407 0.000542819923593424 -0.00759651005583414"
        rpy="0 0 0" />
      <mass
        value="0.000182843437407094" />
      <inertia
        ixx="4.1416606788284E-09"
        ixy="8.21439759639544E-10"
        ixz="-9.55736028363431E-09"
        iyy="2.81778772160108E-08"
        iyz="3.26193789821295E-10"
        izz="2.41118000015193E-08" />
    </inertial>
    <visual>
      <origin
        xyz="0 0 0"
        rpy="0 0 0" />
      <geometry>
        <mesh
          filename="package://rohand_lites_urdf_ros2/meshes_r/mf_connecting_link.STL" />
      </geometry>
      <material
        name="">
        <color
          rgba="1 1 1 1" />
      </material>
    </visual>
    <collision>
      <origin
        xyz="0 0 0"
        rpy="0 0 0" />
      <geometry>
        <mesh
          filename="package://rohand_lites_urdf_ros2/meshes_r/mf_connecting_link.STL" />
      </geometry>
    </collision>
  </link>
  <joint
    name="mf_connecting_link"
    type="continuous">
    <origin
      xyz="-0.11788 -0.0040127 0.010884"
      rpy="0 0 0" />
    <parent
      link="base_link" />
    <child
      link="mf_connecting_link" />
    <axis
      xyz="-0.034181 -0.99942 0.00016502" />
  </joint>
  <link
    name="rf_slider_link">
    <inertial>
      <origin
        xyz="-0.0123925434678941 0.0013011832899389 -5.91653392479248E-05"
        rpy="0 0 0" />
      <mass
        value="0.000366986915741481" />
      <inertia
        ixx="2.51503225174766E-09"
        ixy="2.11557645383335E-09"
        ixz="-9.40785341302129E-11"
        iyy="2.24319140113772E-08"
        iyz="9.8396020921664E-12"
        izz="2.30746417184779E-08" />
    </inertial>
    <visual>
      <origin
        xyz="0 0 0"
        rpy="0 0 0" />
      <geometry>
        <mesh
          filename="package://rohand_lites_urdf_ros2/meshes_r/rf_slider_link.STL" />
      </geometry>
      <material
        name="">
        <color
          rgba="1 1 1 1" />
      </material>
    </visual>
    <collision>
      <origin
        xyz="0 0 0"
        rpy="0 0 0" />
      <geometry>
        <mesh
          filename="package://rohand_lites_urdf_ros2/meshes_r/rf_slider_link.STL" />
      </geometry>
    </collision>
  </link>
  <joint
    name="rf_slider_link"
    type="prismatic">
    <origin
      xyz="-0.073497 0.010248 -0.0025252"
      rpy="0 0 0" />
    <parent
      link="base_link" />
    <child
      link="rf_slider_link" />
    <axis
      xyz="0.99452 -0.10447 0.0047127" />
    <limit
      lower="0"
      upper="0.019"
      effort="0"
      velocity="0" />
  </joint>
  <link
    name="rf_slider_abpart_link">
    <inertial>
      <origin
        xyz="-0.00920645851948901 0.000961227319651661 0.000201860234294676"
        rpy="0 0 0" />
      <mass
        value="0.00030236608370823" />
      <inertia
        ixx="1.07133732553024E-09"
        ixy="2.86152888454119E-10"
        ixz="-1.85529626039528E-10"
        iyy="3.78183383359524E-09"
        iyz="1.93245269929758E-11"
        izz="4.14700876887805E-09" />
    </inertial>
    <visual>
      <origin
        xyz="0 0 0"
        rpy="0 0 0" />
      <geometry>
        <mesh
          filename="package://rohand_lites_urdf_ros2/meshes_r/rf_slider_abpart_link.STL" />
      </geometry>
      <material
        name="">
        <color
          rgba="0.752941176470588 0.752941176470588 0.752941176470588 1" />
      </material>
    </visual>
    <collision>
      <origin
        xyz="0 0 0"
        rpy="0 0 0" />
      <geometry>
        <mesh
          filename="package://rohand_lites_urdf_ros2/meshes_r/rf_slider_abpart_link.STL" />
      </geometry>
    </collision>
  </link>
  <joint
    name="rf_slider_abpart_link"
    type="continuous">
    <origin
      xyz="-0.026553 0.0027935 -0.00012583"
      rpy="0 0 0" />
    <parent
      link="rf_slider_link" />
    <child
      link="rf_slider_abpart_link" />
    <axis
      xyz="-0.10384 -0.99459 -0.00015789" />
  </joint>
  <link
    name="rf_proximal_link">
    <inertial>
      <origin
        xyz="-0.0159252277851225 0.00166363269266015 -0.00261488799317898"
        rpy="0 0 0" />
      <mass
        value="0.00205194161920879" />
      <inertia
        ixx="7.6643328918289E-08"
        ixy="1.18194602082511E-08"
        ixz="1.10284024228161E-08"
        iyy="1.8858407722854E-07"
        iyz="-1.1514316059004E-09"
        izz="2.02173661506433E-07" />
    </inertial>
    <visual>
      <origin
        xyz="0 0 0"
        rpy="0 0 0" />
      <geometry>
        <mesh
          filename="package://rohand_lites_urdf_ros2/meshes_r/rf_proximal_link.STL" />
      </geometry>
      <material
        name="">
        <color
          rgba="1 1 1 1" />
      </material>
    </visual>
    <collision>
      <origin
        xyz="0 0 0"
        rpy="0 0 0" />
      <geometry>
        <mesh
          filename="package://rohand_lites_urdf_ros2/meshes_r/rf_proximal_link.STL" />
      </geometry>
    </collision>
  </link>
  <joint
    name="rf_proximal_link"
    type="continuous">
    <origin
      xyz="-0.1076 0.013828 0.0062414"
      rpy="0 0 0" />
    <parent
      link="base_link" />
    <child
      link="rf_proximal_link" />
    <axis
      xyz="-0.10384 -0.99459 -0.00015789" />
  </joint>
  <link
    name="rf_distal_link">
    <inertial>
      <origin
        xyz="-0.0195774018458887 0.0015697245114497 -0.00435152769479364"
        rpy="0 0 0" />
      <mass
        value="0.00375142011813841" />
      <inertia
        ixx="7.21390681760272E-08"
        ixy="3.35774254403691E-08"
        ixz="-5.77019591811599E-08"
        iyy="4.13946037850212E-07"
        iyz="5.61647586975859E-09"
        izz="4.05901790545028E-07" />
    </inertial>
    <visual>
      <origin
        xyz="0 0 0"
        rpy="0 0 0" />
      <geometry>
        <mesh
          filename="package://rohand_lites_urdf_ros2/meshes_r/rf_distal_link.STL" />
      </geometry>
      <material
        name="">
        <color
          rgba="1 1 1 1" />
      </material>
    </visual>
    <collision>
      <origin
        xyz="0 0 0"
        rpy="0 0 0" />
      <geometry>
        <mesh
          filename="package://rohand_lites_urdf_ros2/meshes_r/rf_distal_link.STL" />
      </geometry>
    </collision>
  </link>
  <joint
    name="rf_distal_link"
    type="continuous">
    <origin
      xyz="-0.032444 0.0036877 -0.00038717"
      rpy="0 0 0" />
    <parent
      link="rf_proximal_link" />
    <child
      link="rf_distal_link" />
    <axis
      xyz="-0.09533 -0.99544 -0.0018704" />
  </joint>
  <link
    name="rf_connecting_link">
    <inertial>
      <origin
        xyz="-0.0139416812293712 0.00145666761808086 -0.00649232687220891"
        rpy="0 0 0" />
      <mass
        value="0.000166925583180313" />
      <inertia
        ixx="2.97303722563927E-09"
        ixy="1.75229428772397E-09"
        ixz="-6.46276437196945E-09"
        iyy="1.95631274561855E-08"
        iyz="6.75211011492413E-10"
        izz="1.69740206257228E-08" />
    </inertial>
    <visual>
      <origin
        xyz="0 0 0"
        rpy="0 0 0" />
      <geometry>
        <mesh
          filename="package://rohand_lites_urdf_ros2/meshes_r/rf_connecting_link.STL" />
      </geometry>
      <material
        name="">
        <color
          rgba="1 1 1 1" />
      </material>
    </visual>
    <collision>
      <origin
        xyz="0 0 0"
        rpy="0 0 0" />
      <geometry>
        <mesh
          filename="package://rohand_lites_urdf_ros2/meshes_r/rf_connecting_link.STL" />
      </geometry>
    </collision>
  </link>
  <joint
    name="rf_connecting_link"
    type="continuous">
    <origin
      xyz="-0.11448 0.014546 0.01021"
      rpy="0 0 0" />
    <parent
      link="base_link" />
    <child
      link="rf_connecting_link" />
    <axis
      xyz="-0.10384 -0.99459 -0.00015789" />
  </joint>
  <link
    name="lf_slider_link">
    <inertial>
      <origin
        xyz="-0.0124139255700257 0.00209500033316999 -5.96958420561212E-05"
        rpy="0 0 0" />
      <mass
        value="0.000362016423224012" />
      <inertia
        ixx="2.67524719530416E-09"
        ixy="2.3796226092674E-09"
        ixz="-6.37314787038461E-11"
        iyy="1.63751713708838E-08"
        iyz="4.7411032913301E-11"
        izz="1.71904269310953E-08" />
    </inertial>
    <visual>
      <origin
        xyz="0 0 0"
        rpy="0 0 0" />
      <geometry>
        <mesh
          filename="package://rohand_lites_urdf_ros2/meshes_r/lf_slider_link.STL" />
      </geometry>
      <material
        name="">
        <color
          rgba="1 1 1 1" />
      </material>
    </visual>
    <collision>
      <origin
        xyz="0 0 0"
        rpy="0 0 0" />
      <geometry>
        <mesh
          filename="package://rohand_lites_urdf_ros2/meshes_r/lf_slider_link.STL" />
      </geometry>
    </collision>
  </link>
  <joint
    name="lf_slider_link"
    type="prismatic">
    <origin
      xyz="-0.069437 0.025465 -0.0048027"
      rpy="0 0 0" />
    <parent
      link="base_link" />
    <child
      link="lf_slider_link" />
    <axis
      xyz="0.98605 -0.16641 0.0047418" />
    <limit
      lower="0"
      upper="0.019"
      effort="0"
      velocity="0" />
  </joint>
  <link
    name="lf_slider_abpart_link">
    <inertial>
      <origin
        xyz="-0.00913180934496972 0.00152541176515186 -8.22246046957992E-05"
        rpy="0 0 0" />
      <mass
        value="0.000302366084373525" />
      <inertia
        ixx="1.12344031803287E-09"
        ixy="4.27187555237878E-10"
        ixz="-2.72000390381376E-10"
        iyy="3.74652696066369E-09"
        iyz="7.37667233434935E-11"
        izz="4.13021270041165E-09" />
    </inertial>
    <visual>
      <origin
        xyz="0 0 0"
        rpy="0 0 0" />
      <geometry>
        <mesh
          filename="package://rohand_lites_urdf_ros2/meshes_r/lf_slider_abpart_link.STL" />
      </geometry>
      <material
        name="">
        <color
          rgba="0.752941176470588 0.752941176470588 0.752941176470588 1" />
      </material>
    </visual>
    <collision>
      <origin
        xyz="0 0 0"
        rpy="0 0 0" />
      <geometry>
        <mesh
          filename="package://rohand_lites_urdf_ros2/meshes_r/lf_slider_abpart_link.STL" />
      </geometry>
    </collision>
  </link>
  <joint
    name="lf_slider_abpart_link"
    type="continuous">
    <origin
      xyz="-0.026334 0.0044017 -0.00012295"
      rpy="0 0 0" />
    <parent
      link="lf_slider_link" />
    <child
      link="lf_slider_abpart_link" />
    <axis
      xyz="-0.1649 -0.98249 0.086708" />
  </joint>
  <link
    name="lf_proximal_link">
    <inertial>
      <origin
        xyz="-0.0142052801661619 0.00208835292624018 -0.00334417355094259"
        rpy="0 0 0" />
      <mass
        value="0.00183689354838277" />
      <inertia
        ixx="6.8848935065652E-08"
        ixy="1.23791411455973E-08"
        ixz="3.07495965694504E-09"
        iyy="1.38925209408907E-07"
        iyz="5.50075119859449E-10"
        izz="1.53064762021108E-07" />
    </inertial>
    <visual>
      <origin
        xyz="0 0 0"
        rpy="0 0 0" />
      <geometry>
        <mesh
          filename="package://rohand_lites_urdf_ros2/meshes_r/lf_proximal_link.STL" />
      </geometry>
      <material
        name="">
        <color
          rgba="1 1 1 1" />
      </material>
    </visual>
    <collision>
      <origin
        xyz="0 0 0"
        rpy="0 0 0" />
      <geometry>
        <mesh
          filename="package://rohand_lites_urdf_ros2/meshes_r/lf_proximal_link.STL" />
      </geometry>
    </collision>
  </link>
  <joint
    name="lf_proximal_link"
    type="continuous">
    <origin
      xyz="-0.1033 0.031912 0.0039331"
      rpy="0 0 0" />
    <parent
      link="base_link" />
    <child
      link="lf_proximal_link" />
    <axis
      xyz="-0.1649 -0.98249 0.086708" />
  </joint>
  <link
    name="lf_distal_link">
    <inertial>
      <origin
        xyz="-0.013895422290453 0.00139953033501757 -0.00580128919808758"
        rpy="0 0 0" />
      <mass
        value="0.0024429507148898" />
      <inertia
        ixx="5.52360011008333E-08"
        ixy="9.09162216777631E-09"
        ixz="-3.45512662870528E-08"
        iyy="1.46710207558064E-07"
        iyz="7.46239468812772E-09"
        izz="1.31472457529192E-07" />
    </inertial>
    <visual>
      <origin
        xyz="0 0 0"
        rpy="0 0 0" />
      <geometry>
        <mesh
          filename="package://rohand_lites_urdf_ros2/meshes_r/lf_distal_link.STL" />
      </geometry>
      <material
        name="">
        <color
          rgba="1 1 1 1" />
      </material>
    </visual>
    <collision>
      <origin
        xyz="0 0 0"
        rpy="0 0 0" />
      <geometry>
        <mesh
          filename="package://rohand_lites_urdf_ros2/meshes_r/lf_distal_link.STL" />
      </geometry>
    </collision>
  </link>
  <joint
    name="lf_distal_link"
    type="continuous">
    <origin
      xyz="-0.028549 0.0048912 -0.00234"
      rpy="0 0 0" />
    <parent
      link="lf_proximal_link" />
    <child
      link="lf_distal_link" />
    <axis
      xyz="-0.1649 -0.98249 0.086708" />
  </joint>
  <link
    name="lf_connecting_link">
    <inertial>
      <origin
        xyz="-0.0116951298240386 0.00131658590471584 -0.00732303507883983"
        rpy="0 0 0" />
      <mass
        value="0.000153788693422294" />
      <inertia
        ixx="3.70334584669705E-09"
        ixy="1.38026266279771E-09"
        ixz="-6.07193618625545E-09"
        iyy="1.49508927556211E-08"
        iyz="7.08632164204691E-10"
        izz="1.16021890608508E-08" />
    </inertial>
    <visual>
      <origin
        xyz="0 0 0"
        rpy="0 0 0" />
      <geometry>
        <mesh
          filename="package://rohand_lites_urdf_ros2/meshes_r/lf_connecting_link.STL" />
      </geometry>
      <material
        name="">
        <color
          rgba="1 1 1 1" />
      </material>
    </visual>
    <collision>
      <origin
        xyz="0 0 0"
        rpy="0 0 0" />
      <geometry>
        <mesh
          filename="package://rohand_lites_urdf_ros2/meshes_r/lf_connecting_link.STL" />
      </geometry>
    </collision>
  </link>
  <joint
    name="lf_connecting_link"
    type="continuous">
    <origin
      xyz="-0.11007 0.033397 0.0078874"
      rpy="0 0 0" />
    <parent
      link="base_link" />
    <child
      link="lf_connecting_link" />
    <axis
      xyz="-0.1649 -0.98249 0.086708" />
  </joint>
  <link
    name="th_root_link">
    <inertial>
      <origin
        xyz="0.00233052829979245 -0.00579711382161271 -0.00109271541396713"
        rpy="0 0 0" />
      <mass
        value="0.00195342720986922" />
      <inertia
        ixx="1.67867472033486E-07"
        ixy="-7.45835056856659E-08"
        ixz="-2.19099067456617E-08"
        iyy="1.86634118448084E-07"
        iyz="-2.85849532829151E-08"
        izz="2.09270905756794E-07" />
    </inertial>
    <visual>
      <origin
        xyz="0 0 0"
        rpy="0 0 0" />
      <geometry>
        <mesh
          filename="package://rohand_lites_urdf_ros2/meshes_r/th_root_link.STL" />
      </geometry>
      <material
        name="">
        <color
          rgba="1 1 1 1" />
      </material>
    </visual>
    <collision>
      <origin
        xyz="0 0 0"
        rpy="0 0 0" />
      <geometry>
        <mesh
          filename="package://rohand_lites_urdf_ros2/meshes_r/th_root_link.STL" />
      </geometry>
    </collision>
  </link>
  <joint
    name="th_root_link"
    type="revolute">
    <origin
      xyz="-0.046829 -0.015748 -0.020109"
      rpy="0 0 0" />
    <parent
      link="base_link" />
    <child
      link="th_root_link" />
    <axis
      xyz="0.97461 -0.034751 0.22118" />
    <limit
      lower="0"
      upper="1.57"
      effort="0"
      velocity="0" />
  </joint>
  <link
    name="th_proximal_link">
    <inertial>
      <origin
        xyz="-0.0182117498020479 -0.0101707279921303 0.00231404301135597"
        rpy="0 0 0" />
      <mass
        value="0.00646400989225721" />
      <inertia
        ixx="7.98428460585965E-07"
        ixy="-6.15671001695266E-07"
        ixz="-2.97783650339316E-07"
        iyy="1.51379481920662E-06"
        iyz="-1.35176390113628E-07"
        izz="2.06093371296286E-06" />
    </inertial>
    <visual>
      <origin
        xyz="0 0 0"
        rpy="0 0 0" />
      <geometry>
        <mesh
          filename="package://rohand_lites_urdf_ros2/meshes_r/th_proximal_link.STL" />
      </geometry>
      <material
        name="">
        <color
          rgba="1 1 1 1" />
      </material>
    </visual>
    <collision>
      <origin
        xyz="0 0 0"
        rpy="0 0 0" />
      <geometry>
        <mesh
          filename="package://rohand_lites_urdf_ros2/meshes_r/th_proximal_link.STL" />
      </geometry>
    </collision>
  </link>
  <joint
    name="th_proximal_link"
    type="continuous">
    <origin
      xyz="-0.0053995 -0.020575 -0.010038"
      rpy="0 0 0" />
    <parent
      link="th_root_link" />
    <child
      link="th_proximal_link" />
    <axis
      xyz="-0.22103 0.0082401 0.97523" />
  </joint>
  <link
    name="th_slider_link">
    <inertial>
      <origin
        xyz="0.00741008273327237 0.00533843502395506 0.00163479233977188"
        rpy="0 0 0" />
      <mass
        value="0.000486787384748644" />
      <inertia
        ixx="3.5939478961123E-08"
        ixy="-2.55423156842415E-08"
        ixz="-4.15800734221228E-09"
        iyy="4.81220421675842E-08"
        iyz="-5.72897565395874E-09"
        izz="5.43431494963031E-08" />
    </inertial>
    <visual>
      <origin
        xyz="0 0 0"
        rpy="0 0 0" />
      <geometry>
        <mesh
          filename="package://rohand_lites_urdf_ros2/meshes_r/th_slider_link.STL" />
      </geometry>
      <material
        name="">
        <color
          rgba="1 1 1 1" />
      </material>
    </visual>
    <collision>
      <origin
        xyz="0 0 0"
        rpy="0 0 0" />
      <geometry>
        <mesh
          filename="package://rohand_lites_urdf_ros2/meshes_r/th_slider_link.STL" />
      </geometry>
    </collision>
  </link>
  <joint
    name="th_slider_link"
    type="prismatic">
    <origin
      xyz="-0.028823 -0.021311 0"
      rpy="0 0 0" />
    <parent
      link="th_proximal_link" />
    <child
      link="th_slider_link" />
    <axis
      xyz="-0.78525 -0.59442 -0.17337" />
    <limit
      lower="0"
      upper="0.01"
      effort="0"
      velocity="0" />
  </joint>
  <link
    name="th_connecting_link">
    <inertial>
      <origin
        xyz="-0.00506186902840118 -0.00240089797646592 -0.000769924940870123"
        rpy="0 0 0" />
      <mass
        value="0.00022981107779302" />
      <inertia
        ixx="1.92151333546619E-09"
        ixy="-6.42770820944338E-10"
        ixz="-2.01975947783555E-10"
        iyy="3.25801491430391E-09"
        iyz="-1.49267320325144E-10"
        izz="2.79216216263212E-09" />
    </inertial>
    <visual>
      <origin
        xyz="0 0 0"
        rpy="0 0 0" />
      <geometry>
        <mesh
          filename="package://rohand_lites_urdf_ros2/meshes_r/th_connecting_link.STL" />
      </geometry>
      <material
        name="">
        <color
          rgba="1 1 1 1" />
      </material>
    </visual>
    <collision>
      <origin
        xyz="0 0 0"
        rpy="0 0 0" />
      <geometry>
        <mesh
          filename="package://rohand_lites_urdf_ros2/meshes_r/th_connecting_link.STL" />
      </geometry>
    </collision>
  </link>
  <joint
    name="th_connecting_link"
    type="continuous">
    <origin
      xyz="-0.0025078 -0.0040122 -0.00084209"
      rpy="0 0 0" />
    <parent
      link="th_slider_link" />
    <child
      link="th_connecting_link" />
    <axis
      xyz="-0.22103 0.0082401 0.97523" />
  </joint>
  <link
    name="th_distal_link">
    <inertial>
      <origin
        xyz="-0.00521740963298763 -0.00978816723840009 -0.000840496545300051"
        rpy="0 0 0" />
      <mass
        value="0.00460659233357567" />
      <inertia
        ixx="2.17350071314894E-07"
        ixy="-5.78129756742083E-08"
        ixz="-9.00254190204992E-09"
        iyy="2.41402355455659E-07"
        iyz="-1.29521685085698E-08"
        izz="2.57313048584919E-07" />
    </inertial>
    <visual>
      <origin
        xyz="0 0 0"
        rpy="0 0 0" />
      <geometry>
        <mesh
          filename="package://rohand_lites_urdf_ros2/meshes_r/th_distal_link.STL" />
      </geometry>
      <material
        name="">
        <color
          rgba="1 1 1 1" />
      </material>
    </visual>
    <collision>
      <origin
        xyz="0 0 0"
        rpy="0 0 0" />
      <geometry>
        <mesh
          filename="package://rohand_lites_urdf_ros2/meshes_r/th_distal_link.STL" />
      </geometry>
    </collision>
  </link>
  <joint
    name="th_distal_link"
    type="continuous">
    <origin
      xyz="-0.04565 -0.02065 -0.0040713"
      rpy="0 0 0" />
    <parent
      link="th_proximal_link" />
    <child
      link="th_distal_link" />
    <axis
      xyz="-0.22103 0.00824 0.97523" />
  </joint>
</robot>