<?xml version="1.0" encoding="utf-8"?>
<!-- This URDF was automatically created by SolidWorks to URDF Exporter! Originally created by Stephen Brawner (brawner@gmail.com) 
     Commit Version: 1.6.0-4-g7f85cfe  Build Version: 1.6.7995.38578
     For more information, please see http://wiki.ros.org/sw_urdf_exporter -->
<robot
  name="rohand_right">
  <link
    name="base_link">
    <inertial>
      <origin
        xyz="-0.0576030661180955 0.00233560896319593 -0.00133218779459777"
        rpy="0 0 0" />
      <mass
        value="0.0493249140792959" />
      <inertia
        ixx="1.94571823302338E-05"
        ixy="-1.38729153384568E-06"
        ixz="1.07807983669446E-06"
        iyy="2.67719341990073E-05"
        iyz="-3.07356342974464E-07"
        izz="4.02773132726367E-05" />
    </inertial>
    <visual>
      <origin
        xyz="0 0 0"
        rpy="0 0 0" />
      <geometry>
        <mesh
          filename="package://rohand_lites_urdf_ros2/meshes_r/base_link.STL" />
      </geometry>
      <material
        name="">
        <color
          rgba="1 1 1 1" />
      </material>
    </visual>
    <collision>
      <origin
        xyz="0 0 0"
        rpy="0 0 0" />
      <geometry>
        <mesh
          filename="package://rohand_lites_urdf_ros2/meshes_r/base_link.STL" />
      </geometry>
    </collision>
  </link>
  <link
    name="if_slider_link">
    <inertial>
      <origin
        xyz="-0.0124609670249795 -6.05568753975216E-07 -4.50638596504599E-07"
        rpy="0 0 0" />
      <mass
        value="0.000366972973274265" />
      <inertia
        ixx="2.29233464715096E-09"
        ixy="-2.11951620782461E-13"
        ixz="3.23564730293183E-12"
        iyy="2.26563978264393E-08"
        iyz="-3.63741608833748E-11"
        izz="2.30712176924516E-08" />
    </inertial>
    <visual>
      <origin
        xyz="0 0 0"
        rpy="0 0 0" />
      <geometry>
        <mesh
          filename="package://rohand_lites_urdf_ros2/meshes_r/if_slider_link.STL" />
      </geometry>
      <material
        name="">
        <color
          rgba="1 1 1 1" />
      </material>
    </visual>
    <collision>
      <origin
        xyz="0 0 0"
        rpy="0 0 0" />
      <geometry>
        <mesh
          filename="package://rohand_lites_urdf_ros2/meshes_r/if_slider_link.STL" />
      </geometry>
    </collision>
  </link>
  <joint
    name="if_slider_link"
    type="prismatic">
    <origin
      xyz="-0.071447 -0.020467 -0.0095174"
      rpy="-0.00016113 -0.0046058 0.034971" />
    <parent
      link="base_link" />
    <child
      link="if_slider_link" />
    <axis
      xyz="1 0 0" />
    <limit
      lower="-0.003"
      upper="0.016"
      effort="0"
      velocity="0" />
  </joint>
  <link
    name="if_slider_abpart_link">
    <inertial>
      <origin
        xyz="-0.00866373189337132 0.00290002129476075 -0.00105148512166708"
        rpy="0 0 0" />
      <mass
        value="0.000320776973378262" />
      <inertia
        ixx="1.21251133354517E-09"
        ixy="1.12575862233581E-15"
        ixz="-6.15815769360825E-10"
        iyy="3.82102738103043E-09"
        iyz="7.37152612173675E-15"
        izz="4.08771458748549E-09" />
    </inertial>
    <visual>
      <origin
        xyz="0 0 0"
        rpy="0 0 0" />
      <geometry>
        <mesh
          filename="package://rohand_lites_urdf_ros2/meshes_r/if_slider_abpart_link.STL" />
      </geometry>
      <material
        name="">
        <color
          rgba="1 1 1 1" />
      </material>
    </visual>
    <collision>
      <origin
        xyz="0 0 0"
        rpy="0 0 0" />
      <geometry>
        <mesh
          filename="package://rohand_lites_urdf_ros2/meshes_r/if_slider_abpart_link.STL" />
      </geometry>
    </collision>
  </link>
  <joint
    name="if_slider_abpart_link"
    type="continuous">
    <origin
      xyz="-0.026698 -0.0028819 -0.0002512"
      rpy="0.086944 0.0014956 0.00076252" />
    <parent
      link="if_slider_link" />
    <child
      link="if_slider_abpart_link" />
    <axis
      xyz="0 1 0" />
  </joint>
  <link
    name="if_proximal_link">
    <inertial>
      <origin
        xyz="-0.0143787205756178 0.0068202042615699 -0.00751216413311831"
        rpy="0 0 0" />
      <mass
        value="0.00205183706838826" />
      <inertia
        ixx="8.13016698160853E-08"
        ixy="1.51094306482205E-11"
        ixz="-2.88949821390807E-08"
        iyy="1.89783171251403E-07"
        iyz="4.65572959060812E-12"
        izz="1.96251769923446E-07" />
    </inertial>
    <visual>
      <origin
        xyz="0 0 0"
        rpy="0 0 0" />
      <geometry>
        <mesh
          filename="package://rohand_lites_urdf_ros2/meshes_r/if_proximal_link.STL" />
      </geometry>
      <material
        name="">
        <color
          rgba="1 1 1 1" />
      </material>
    </visual>
    <collision>
      <origin
        xyz="0 0 0"
        rpy="0 0 0" />
      <geometry>
        <mesh
          filename="package://rohand_lites_urdf_ros2/meshes_r/if_proximal_link.STL" />
      </geometry>
    </collision>
  </link>
  <joint
    name="if_proximal_link"
    type="continuous">
    <origin
      xyz="-0.10859 -0.029338 -0.0013861"
      rpy="0.086779 -0.00311 0.035733" />
    <parent
      link="base_link" />
    <child
      link="if_proximal_link" />
    <axis
      xyz="0 1 0" />
  </joint>
  <link
    name="if_distal_link">
    <inertial>
      <origin
        xyz="-0.012222373112902 0.00644744577874212 -0.0159308052491082"
        rpy="0 0 0" />
      <mass
        value="0.00375868071914677" />
      <inertia
        ixx="2.6526744005835E-07"
        ixy="2.68139132185787E-10"
        ixz="-1.76013365071367E-07"
        iyy="4.17225025361236E-07"
        iyz="3.16739936806118E-10"
        izz="2.09518827365182E-07" />
    </inertial>
    <visual>
      <origin
        xyz="0 0 0"
        rpy="0 0 0" />
      <geometry>
        <mesh
          filename="package://rohand_lites_urdf_ros2/meshes_r/if_distal_link.STL" />
      </geometry>
      <material
        name="">
        <color
          rgba="1 1 1 1" />
      </material>
    </visual>
    <collision>
      <origin
        xyz="0 0 0"
        rpy="0 0 0" />
      <geometry>
        <mesh
          filename="package://rohand_lites_urdf_ros2/meshes_r/if_distal_link.STL" />
      </geometry>
    </collision>
  </link>
  <joint
    name="if_distal_link"
    type="continuous">
    <origin
      xyz="-0.030875 0.00036803 -0.010625"
      rpy="0 0 0" />
    <parent
      link="if_proximal_link" />
    <child
      link="if_distal_link" />
    <axis
      xyz="0 1 0" />
  </joint>
  <link
    name="if_connecting_link">
    <inertial>
      <origin
        xyz="-0.0102235152152293 0.00327000024503699 -0.0115810886981339"
        rpy="0 0 0" />
      <mass
        value="0.000166926122979652" />
      <inertia
        ixx="9.86848066859747E-09"
        ixy="-2.79492599949535E-16"
        ixz="-9.61873949323938E-09"
        iyy="1.97462229470862E-08"
        iyz="-2.13641840030211E-16"
        izz="9.89554770092519E-09" />
    </inertial>
    <visual>
      <origin
        xyz="0 0 0"
        rpy="0 0 0" />
      <geometry>
        <mesh
          filename="package://rohand_lites_urdf_ros2/meshes_r/if_connecting_link.STL" />
      </geometry>
      <material
        name="">
        <color
          rgba="1 1 1 1" />
      </material>
    </visual>
    <collision>
      <origin
        xyz="0 0 0"
        rpy="0 0 0" />
      <geometry>
        <mesh
          filename="package://rohand_lites_urdf_ros2/meshes_r/if_connecting_link.STL" />
      </geometry>
    </collision>
  </link>
  <joint
    name="if_connecting_link"
    type="continuous">
    <origin
      xyz="-0.11562 -0.026397 0.0028757"
      rpy="0.086779 -0.00311 0.035733" />
    <parent
      link="base_link" />
    <child
      link="if_connecting_link" />
    <axis
      xyz="0 1 0" />
  </joint>
  <link
    name="mf_slider_link">
    <inertial>
      <origin
        xyz="-0.0124609522099025 6.3916828382804E-07 3.92633961801558E-07"
        rpy="0 0 0" />
      <mass
        value="0.000366973958523744" />
      <inertia
        ixx="2.2923356136903E-09"
        ixy="-5.90590014144133E-14"
        ixz="-3.22023842512374E-12"
        iyy="2.26532695755211E-08"
        iyz="1.63982269743846E-13"
        izz="2.30744115879956E-08" />
    </inertial>
    <visual>
      <origin
        xyz="0 0 0"
        rpy="0 0 0" />
      <geometry>
        <mesh
          filename="package://rohand_lites_urdf_ros2/meshes_r/mf_slider_link.STL" />
      </geometry>
      <material
        name="">
        <color
          rgba="1 1 1 1" />
      </material>
    </visual>
    <collision>
      <origin
        xyz="0 0 0"
        rpy="0 0 0" />
      <geometry>
        <mesh
          filename="package://rohand_lites_urdf_ros2/meshes_r/mf_slider_link.STL" />
      </geometry>
    </collision>
  </link>
  <joint
    name="mf_slider_link"
    type="prismatic">
    <origin
      xyz="-0.073238 -0.005607 -0.0056506"
      rpy="0.00015832 -0.0046649 -0.033926" />
    <parent
      link="base_link" />
    <child
      link="mf_slider_link" />
    <axis
      xyz="1 0 0" />
    <limit
      lower="-0.003"
      upper="0.016"
      effort="0"
      velocity="0" />
  </joint>
  <link
    name="mf_slider_abpart_link">
    <inertial>
      <origin
        xyz="-0.00863166357507834 0.00290002131146788 -0.00128850892261363"
        rpy="0 0 0" />
      <mass
        value="0.000320776973597363" />
      <inertia
        ixx="1.24840916152964E-09"
        ixy="8.9268064313087E-16"
        ixz="-6.93652604531175E-10"
        iyy="3.82102737674027E-09"
        iyz="7.39393958291175E-15"
        izz="4.05181677204681E-09" />
    </inertial>
    <visual>
      <origin
        xyz="0 0 0"
        rpy="0 0 0" />
      <geometry>
        <mesh
          filename="package://rohand_lites_urdf_ros2/meshes_r/mf_slider_abpart_link.STL" />
      </geometry>
      <material
        name="">
        <color
          rgba="1 1 1 1" />
      </material>
    </visual>
    <collision>
      <origin
        xyz="0 0 0"
        rpy="0 0 0" />
      <geometry>
        <mesh
          filename="package://rohand_lites_urdf_ros2/meshes_r/mf_slider_abpart_link.STL" />
      </geometry>
    </collision>
  </link>
  <joint
    name="mf_slider_abpart_link"
    type="continuous">
    <origin
      xyz="-0.026701 -0.0028167 0"
      rpy="-0.00032457 0.0046592 -0.0002623" />
    <parent
      link="mf_slider_link" />
    <child
      link="mf_slider_abpart_link" />
    <axis
      xyz="0 1 0" />
  </joint>
  <link
    name="mf_proximal_link">
    <inertial>
      <origin
        xyz="-0.016329453759154 0.00649226533975397 -0.00963384586033489"
        rpy="0 0 0" />
      <mass
        value="0.00248843296883051" />
      <inertia
        ixx="1.10610510723197E-07"
        ixy="-5.89496390356217E-11"
        ixz="-6.05126652788143E-08"
        iyy="2.8446139484122E-07"
        iyz="-4.21063735821963E-11"
        izz="2.7312514865437E-07" />
    </inertial>
    <visual>
      <origin
        xyz="0 0 0"
        rpy="0 0 0" />
      <geometry>
        <mesh
          filename="package://rohand_lites_urdf_ros2/meshes_r/mf_proximal_link.STL" />
      </geometry>
      <material
        name="">
        <color
          rgba="1 1 1 1" />
      </material>
    </visual>
    <collision>
      <origin
        xyz="0 0 0"
        rpy="0 0 0" />
      <geometry>
        <mesh
          filename="package://rohand_lites_urdf_ros2/meshes_r/mf_proximal_link.STL" />
      </geometry>
    </collision>
  </link>
  <joint
    name="mf_proximal_link"
    type="continuous">
    <origin
      xyz="-0.111168350336371 -0.0107315849401363 0.00310533319557881"
      rpy="-0.000165024105879644 0 -0.0341875332667528" />
    <parent
      link="base_link" />
    <child
      link="mf_proximal_link" />
    <axis
      xyz="0 1 0" />
  </joint>
  <link
    name="mf_distal_link">
    <inertial>
      <origin
        xyz="-0.0117807102189178 0.00644198393359627 -0.0162599790204698"
        rpy="0 0 0" />
      <mass
        value="0.00375867884267013" />
      <inertia
        ixx="2.74876926237726E-07"
        ixy="2.59466981378291E-10"
        ixz="-1.7421907947615E-07"
        iyy="4.1722285891413E-07"
        iyz="3.23406111565757E-10"
        izz="1.99906902685593E-07" />
    </inertial>
    <visual>
      <origin
        xyz="0 0 0"
        rpy="0 0 0" />
      <geometry>
        <mesh
          filename="package://rohand_lites_urdf_ros2/meshes_r/mf_distal_link.STL" />
      </geometry>
      <material
        name="">
        <color
          rgba="1 1 1 1" />
      </material>
    </visual>
    <collision>
      <origin
        xyz="0 0 0"
        rpy="0 0 0" />
      <geometry>
        <mesh
          filename="package://rohand_lites_urdf_ros2/meshes_r/mf_distal_link.STL" />
      </geometry>
    </collision>
  </link>
  <joint
    name="mf_distal_link"
    type="continuous">
    <origin
      xyz="-0.0348440227740655 5.03497035553302E-05 -0.0137271073982339"
      rpy="-0.00439882751506536 -0.000117257737364924 0.00753742768873965" />
    <parent
      link="mf_proximal_link" />
    <child
      link="mf_distal_link" />
    <axis
      xyz="0 1 0" />
  </joint>
  <link
    name="mf_connecting_link">
    <inertial>
      <origin
        xyz="-0.0118629043806557 0.00295000036089821 -0.0130519870915176"
        rpy="0 0 0" />
      <mass
        value="0.000182841546424983" />
      <inertia
        ixx="1.36693669202092E-08"
        ixy="-6.13942202718969E-17"
        ixz="-1.38287133151985E-08"
        iyy="2.82058000519108E-08"
        iyz="-1.29081234194706E-16"
        izz="1.45559363439041E-08" />
    </inertial>
    <visual>
      <origin
        xyz="0 0 0"
        rpy="0 0 0" />
      <geometry>
        <mesh
          filename="package://rohand_lites_urdf_ros2/meshes_r/mf_connecting_link.STL" />
      </geometry>
      <material
        name="">
        <color
          rgba="1 1 1 1" />
      </material>
    </visual>
    <collision>
      <origin
        xyz="0 0 0"
        rpy="0 0 0" />
      <geometry>
        <mesh
          filename="package://rohand_lites_urdf_ros2/meshes_r/mf_connecting_link.STL" />
      </geometry>
    </collision>
  </link>
  <joint
    name="mf_connecting_link"
    type="continuous">
    <origin
      xyz="-0.117961503708004 -0.00695063768300233 0.00707421346498281"
      rpy="-0.000165024105881287 0 -0.0341875332667273" />
    <parent
      link="base_link" />
    <child
      link="mf_connecting_link" />
    <axis
      xyz="0 1 0" />
  </joint>
  <link
    name="rf_slider_link">
    <inertial>
      <origin
        xyz="-0.0124609668654551 -6.42523672919615E-07 -3.96232102715249E-07"
        rpy="0 0 0" />
      <mass
        value="0.000366972980545594" />
      <inertia
        ixx="2.29233465655508E-09"
        ixy="7.0469841726488E-14"
        ixz="3.24194481698336E-12"
        iyy="2.26532326662844E-08"
        iyz="1.57491659496596E-13"
        izz="2.30743832122343E-08" />
    </inertial>
    <visual>
      <origin
        xyz="0 0 0"
        rpy="0 0 0" />
      <geometry>
        <mesh
          filename="package://rohand_lites_urdf_ros2/meshes_r/rf_slider_link.STL" />
      </geometry>
      <material
        name="">
        <color
          rgba="1 1 1 1" />
      </material>
    </visual>
    <collision>
      <origin
        xyz="0 0 0"
        rpy="0 0 0" />
      <geometry>
        <mesh
          filename="package://rohand_lites_urdf_ros2/meshes_r/rf_slider_link.STL" />
      </geometry>
    </collision>
  </link>
  <joint
    name="rf_slider_link"
    type="prismatic">
    <origin
      xyz="-0.070347 0.0099293 -0.0063203"
      rpy="0.00049505 -0.0047127 -0.10466" />
    <parent
      link="base_link" />
    <child
      link="rf_slider_link" />
    <axis
      xyz="1 0 0" />
    <limit
      lower="-0.003"
      upper="0.016"
      effort="0"
      velocity="0" />
  </joint>
  <link
    name="rf_slider_abpart_link">
    <inertial>
      <origin
        xyz="-0.0100885934163083 -0.0147819374305474 -0.000191629038160966"
        rpy="0 0 0" />
      <mass
        value="0.000320776973678139" />
      <inertia
        ixx="1.20862127023145E-09"
        ixy="-1.07830758701414E-10"
        ixz="-5.93641078541842E-10"
        iyy="3.81973217202437E-09"
        iyz="-6.03311477161355E-11"
        izz="4.09289987747545E-09" />
    </inertial>
    <visual>
      <origin
        xyz="0 0 0"
        rpy="0 0 0" />
      <geometry>
        <mesh
          filename="package://rohand_lites_urdf_ros2/meshes_r/rf_slider_abpart_link.STL" />
      </geometry>
      <material
        name="">
        <color
          rgba="1 1 1 1" />
      </material>
    </visual>
    <collision>
      <origin
        xyz="0 0 0"
        rpy="0 0 0" />
      <geometry>
        <mesh
          filename="package://rohand_lites_urdf_ros2/meshes_r/rf_slider_abpart_link.STL" />
      </geometry>
    </collision>
  </link>
  <joint
    name="rf_slider_abpart_link"
    type="continuous">
    <origin
      xyz="-0.024396 0.014106 -0.0020413"
      rpy="-0.087604 -0.0098226 -0.060353" />
    <parent
      link="rf_slider_link" />
    <child
      link="rf_slider_abpart_link" />
    <axis
      xyz="0 1 0" />
  </joint>
  <link
    name="rf_proximal_link">
    <inertial>
      <origin
        xyz="-0.0143549280434906 0.00682023657911832 -0.00755778479766486"
        rpy="0 0 0" />
      <mass
        value="0.00205187294843744" />
      <inertia
        ixx="8.14868585707663E-08"
        ixy="1.41861573407726E-11"
        ixz="-2.9259876910324E-08"
        iyy="1.89786107772236E-07"
        iyz="4.79988274178486E-12"
        izz="1.960702878707E-07" />
    </inertial>
    <visual>
      <origin
        xyz="0 0 0"
        rpy="0 0 0" />
      <geometry>
        <mesh
          filename="package://rohand_lites_urdf_ros2/meshes_r/rf_proximal_link.STL" />
      </geometry>
      <material
        name="">
        <color
          rgba="1 1 1 1" />
      </material>
    </visual>
    <collision>
      <origin
        xyz="0 0 0"
        rpy="0 0 0" />
      <geometry>
        <mesh
          filename="package://rohand_lites_urdf_ros2/meshes_r/rf_proximal_link.STL" />
      </geometry>
    </collision>
  </link>
  <joint
    name="rf_proximal_link"
    type="continuous">
    <origin
      xyz="-0.10829 0.007056 0.0024304"
      rpy="0.00015789 1.6485E-05 -0.10403" />
    <parent
      link="base_link" />
    <child
      link="rf_proximal_link" />
    <axis
      xyz="0 1 0" />
  </joint>
  <link
    name="rf_distal_link">
    <inertial>
      <origin
        xyz="-0.0121787543720058 0.0064475580290749 -0.0159643969071744"
        rpy="0 0 0" />
      <mass
        value="0.00375873422510174" />
      <inertia
        ixx="2.66234188468105E-07"
        ixy="2.66619623996111E-10"
        ixz="-1.75861376428997E-07"
        iyy="4.17230114265725E-07"
        iyz="3.17193421265111E-10"
        izz="2.0855875648093E-07" />
    </inertial>
    <visual>
      <origin
        xyz="0 0 0"
        rpy="0 0 0" />
      <geometry>
        <mesh
          filename="package://rohand_lites_urdf_ros2/meshes_r/rf_distal_link.STL" />
      </geometry>
      <material
        name="">
        <color
          rgba="1 1 1 1" />
      </material>
    </visual>
    <collision>
      <origin
        xyz="0 0 0"
        rpy="0 0 0" />
      <geometry>
        <mesh
          filename="package://rohand_lites_urdf_ros2/meshes_r/rf_distal_link.STL" />
      </geometry>
    </collision>
  </link>
  <joint
    name="rf_distal_link"
    type="continuous">
    <origin
      xyz="-0.030791 0.00036828 -0.010696"
      rpy="-0.0042136 -0.0004074 0.0076437" />
    <parent
      link="rf_proximal_link" />
    <child
      link="rf_distal_link" />
    <axis
      xyz="0 1 0" />
  </joint>
  <link
    name="rf_connecting_link">
    <inertial>
      <origin
        xyz="-0.0101867238855837 0.00327000024099278 -0.0116134634575045"
        rpy="0 0 0" />
      <mass
        value="0.000166926124302073" />
      <inertia
        ixx="9.92950962516541E-09"
        ixy="-2.74038817651999E-16"
        ixz="-9.61863178709265E-09"
        iyy="1.97462230124827E-08"
        iyz="-2.10896337349332E-16"
        izz="9.83451880987801E-09" />
    </inertial>
    <visual>
      <origin
        xyz="0 0 0"
        rpy="0 0 0" />
      <geometry>
        <mesh
          filename="package://rohand_lites_urdf_ros2/meshes_r/rf_connecting_link.STL" />
      </geometry>
      <material
        name="">
        <color
          rgba="1 1 1 1" />
      </material>
    </visual>
    <collision>
      <origin
        xyz="0 0 0"
        rpy="0 0 0" />
      <geometry>
        <mesh
          filename="package://rohand_lites_urdf_ros2/meshes_r/rf_connecting_link.STL" />
      </geometry>
    </collision>
  </link>
  <joint
    name="rf_connecting_link"
    type="continuous">
    <origin
      xyz="-0.1148 0.011304 0.0063998"
      rpy="0.00015789 1.6485E-05 -0.10403" />
    <parent
      link="base_link" />
    <child
      link="rf_connecting_link" />
    <axis
      xyz="0 1 0" />
  </joint>
  <link
    name="lf_slider_link">
    <inertial>
      <origin
        xyz="-0.0125896488936118 1.55933339851533E-09 2.23438139171361E-09"
        rpy="0 0 0" />
      <mass
        value="0.000362010956124095" />
      <inertia
        ixx="2.27333564814737E-09"
        ixy="6.45925406914816E-17"
        ixz="2.27140551808567E-15"
        iyy="1.67765596657493E-08"
        iyz="3.64789784906076E-11"
        izz="1.71905369724548E-08" />
    </inertial>
    <visual>
      <origin
        xyz="0 0 0"
        rpy="0 0 0" />
      <geometry>
        <mesh
          filename="package://rohand_lites_urdf_ros2/meshes_r/lf_slider_link.STL" />
      </geometry>
      <material
        name="">
        <color
          rgba="1 1 1 1" />
      </material>
    </visual>
    <collision>
      <origin
        xyz="0 0 0"
        rpy="0 0 0" />
      <geometry>
        <mesh
          filename="package://rohand_lites_urdf_ros2/meshes_r/lf_slider_link.STL" />
      </geometry>
    </collision>
  </link>
  <joint
    name="lf_slider_link"
    type="prismatic">
    <origin
      xyz="-0.066313 0.024951 -0.0085977"
      rpy="0.00080024 -0.0047418 -0.16719" />
    <parent
      link="base_link" />
    <child
      link="lf_slider_link" />
    <axis
      xyz="1 0 0" />
    <limit
      lower="-0.003"
      upper="0.016"
      effort="0"
      velocity="0" />
  </joint>
  <link
    name="lf_slider_abpart_link">
    <inertial>
      <origin
        xyz="-0.00865091200755626 0.00290002130581088 -0.0011522121204514"
        rpy="0 0 0" />
      <mass
        value="0.000320776973239087" />
      <inertia
        ixx="1.22722897670156E-09"
        ixy="1.01927582998155E-15"
        ixz="-6.49098338911124E-10"
        iyy="3.82102736915005E-09"
        iyz="7.38003662354594E-15"
        izz="4.07299694248471E-09" />
    </inertial>
    <visual>
      <origin
        xyz="0 0 0"
        rpy="0 0 0" />
      <geometry>
        <mesh
          filename="package://rohand_lites_urdf_ros2/meshes_r/lf_slider_abpart_link.STL" />
      </geometry>
      <material
        name="">
        <color
          rgba="1 1 1 1" />
      </material>
    </visual>
    <collision>
      <origin
        xyz="0 0 0"
        rpy="0 0 0" />
      <geometry>
        <mesh
          filename="package://rohand_lites_urdf_ros2/meshes_r/lf_slider_abpart_link.STL" />
      </geometry>
    </collision>
  </link>
  <joint
    name="lf_slider_abpart_link"
    type="continuous">
    <origin
      xyz="-0.026696 -0.0029267 0.00025708"
      rpy="-0.087616 -0.0097532 0.0021703" />
    <parent
      link="lf_slider_link" />
    <child
      link="lf_slider_abpart_link" />
    <axis
      xyz="0 1 0" />
  </joint>
  <link
    name="lf_proximal_link">
    <inertial>
      <origin
        xyz="-0.0127241110356107 0.00649957990170523 -0.00744483846071534"
        rpy="0 0 0" />
      <mass
        value="0.00183686407359195" />
      <inertia
        ixx="7.25936420936618E-08"
        ixy="1.26029064472353E-12"
        ixz="-2.19325321953627E-08"
        iyy="1.40948330406022E-07"
        iyz="-3.97609924901949E-13"
        izz="1.47282231216297E-07" />
    </inertial>
    <visual>
      <origin
        xyz="0 0 0"
        rpy="0 0 0" />
      <geometry>
        <mesh
          filename="package://rohand_lites_urdf_ros2/meshes_r/lf_proximal_link.STL" />
      </geometry>
      <material
        name="">
        <color
          rgba="1 1 1 1" />
      </material>
    </visual>
    <collision>
      <origin
        xyz="0 0 0"
        rpy="0 0 0" />
      <geometry>
        <mesh
          filename="package://rohand_lites_urdf_ros2/meshes_r/lf_proximal_link.STL" />
      </geometry>
    </collision>
  </link>
  <joint
    name="lf_proximal_link"
    type="continuous">
    <origin
      xyz="-0.10436 0.025536 0.00068678"
      rpy="-0.086826 -0.014497 -0.16502" />
    <parent
      link="base_link" />
    <child
      link="lf_proximal_link" />
    <axis
      xyz="0 1 0" />
  </joint>
  <link
    name="lf_distal_link">
    <inertial>
      <origin
        xyz="-0.00660185291159945 0.00644841570480648 -0.0134694736191499"
        rpy="0 0 0" />
      <mass
        value="0.00243556509111398" />
      <inertia
        ixx="1.18626211477515E-07"
        ixy="9.45828083556239E-11"
        ixz="-4.33572574582032E-08"
        iyy="1.41808396396924E-07"
        iyz="1.67029567238108E-10"
        izz="5.46901618733586E-08" />
    </inertial>
    <visual>
      <origin
        xyz="0 0 0"
        rpy="0 0 0" />
      <geometry>
        <mesh
          filename="package://rohand_lites_urdf_ros2/meshes_r/lf_distal_link.STL" />
      </geometry>
      <material
        name="">
        <color
          rgba="1 1 1 1" />
      </material>
    </visual>
    <collision>
      <origin
        xyz="0 0 0"
        rpy="0 0 0" />
      <geometry>
        <mesh
          filename="package://rohand_lites_urdf_ros2/meshes_r/lf_distal_link.STL" />
      </geometry>
    </collision>
  </link>
  <joint
    name="lf_distal_link"
    type="continuous">
    <origin
      xyz="-0.026989 5.0837E-05 -0.010769"
      rpy="0 0 0" />
    <parent
      link="lf_proximal_link" />
    <child
      link="lf_distal_link" />
    <axis
      xyz="0 1 0" />
  </joint>
  <link
    name="lf_connecting_link">
    <inertial>
      <origin
        xyz="-0.00795535243158465 0.00295000051882525 -0.0113514271923212"
        rpy="0 0 0" />
      <mass
        value="0.000153787132130572" />
      <inertia
        ixx="9.18085783637836E-09"
        ixy="-8.89966691097565E-17"
        ixz="-7.14261803972651E-09"
        iyy="1.51199802903836E-08"
        iyz="-3.00265539547922E-16"
        izz="5.95552642892441E-09" />
    </inertial>
    <visual>
      <origin
        xyz="0 0 0"
        rpy="0 0 0" />
      <geometry>
        <mesh
          filename="package://rohand_lites_urdf_ros2/meshes_r/lf_connecting_link.STL" />
      </geometry>
      <material
        name="">
        <color
          rgba="1 1 1 1" />
      </material>
    </visual>
    <collision>
      <origin
        xyz="0 0 0"
        rpy="0 0 0" />
      <geometry>
        <mesh
          filename="package://rohand_lites_urdf_ros2/meshes_r/lf_connecting_link.STL" />
      </geometry>
    </collision>
  </link>
  <joint
    name="lf_connecting_link"
    type="continuous">
    <origin
      xyz="-0.11054 0.030508 0.0043333"
      rpy="-0.086826 -0.014497 -0.16502" />
    <parent
      link="base_link" />
    <child
      link="lf_connecting_link" />
    <axis
      xyz="0 1 0" />
  </joint>
  <link
    name="th_root_link">
    <inertial>
      <origin
        xyz="-0.0191686509683619 -0.00572418793751744 -0.00158132841516827"
        rpy="0 0 0" />
      <mass
        value="0.00195350966248874" />
      <inertia
        ixx="1.65972225377993E-07"
        ixy="-7.97825490860689E-08"
        ixz="-1.04261831309922E-08"
        iyy="1.8111092952085E-07"
        iyz="-1.1733271461248E-08"
        izz="2.16718599283951E-07" />
    </inertial>
    <visual>
      <origin
        xyz="0 0 0"
        rpy="0 0 0" />
      <geometry>
        <mesh
          filename="package://rohand_lites_urdf_ros2/meshes_r/th_root_link.STL" />
      </geometry>
      <material
        name="">
        <color
          rgba="1 1 1 1" />
      </material>
    </visual>
    <collision>
      <origin
        xyz="0 0 0"
        rpy="0 0 0" />
      <geometry>
        <mesh
          filename="package://rohand_lites_urdf_ros2/meshes_r/th_root_link.STL" />
      </geometry>
    </collision>
  </link>
  <joint
    name="th_root_link"
    type="revolute">
    <origin
      xyz="-0.025954 -0.01648 -0.019186"
      rpy="0.0078865 -0.22303 -0.035641" />
    <parent
      link="base_link" />
    <child
      link="th_root_link" />
    <axis
      xyz="1 0 0" />
    <limit
      lower="0"
      upper="1.57"
      effort="0"
      velocity="0" />
  </joint>
  <link
    name="th_proximal_link">
    <inertial>
      <origin
        xyz="-0.0190126820702974 -0.00637807841543053 0.00769785866417869"
        rpy="0 0 0" />
      <mass
        value="0.00646388849033333" />
      <inertia
        ixx="5.07687345462868E-07"
        ixy="-4.14559349698037E-07"
        ixz="-1.8674365709823E-09"
        iyy="1.73768654791953E-06"
        iyz="-4.20029512218484E-10"
        izz="2.12756394178572E-06" />
    </inertial>
    <visual>
      <origin
        xyz="0 0 0"
        rpy="0 0 0" />
      <geometry>
        <mesh
          filename="package://rohand_lites_urdf_ros2/meshes_r/th_proximal_link.STL" />
      </geometry>
      <material
        name="">
        <color
          rgba="1 1 1 1" />
      </material>
    </visual>
    <collision>
      <origin
        xyz="0 0 0"
        rpy="0 0 0" />
      <geometry>
        <mesh
          filename="package://rohand_lites_urdf_ros2/meshes_r/th_proximal_link.STL" />
      </geometry>
    </collision>
  </link>
  <joint
    name="th_proximal_link"
    type="continuous">
    <origin
      xyz="-0.028168 -0.020837 -0.010094"
      rpy="-0.0082402 0.00028649 0.034758" />
    <parent
      link="th_root_link" />
    <child
      link="th_proximal_link" />
    <axis
      xyz="0 0 1" />
  </joint>
  <link
    name="th_slider_link">
    <inertial>
      <origin
        xyz="0.0102453198231892 0.00126427543867116 1.08406227390806E-05"
        rpy="0 0 0" />
      <mass
        value="0.000954853800364086" />
      <inertia
        ixx="2.43406780273046E-08"
        ixy="1.43072256909216E-09"
        ixz="1.33936712939083E-11"
        iyy="7.82508263001173E-08"
        iyz="1.60851724924034E-10"
        izz="6.04003861889419E-08" />
    </inertial>
    <visual>
      <origin
        xyz="0 0 0"
        rpy="0 0 0" />
      <geometry>
        <mesh
          filename="package://rohand_lites_urdf_ros2/meshes_r/th_slider_link.STL" />
      </geometry>
      <material
        name="">
        <color
          rgba="1 1 1 1" />
      </material>
    </visual>
    <collision>
      <origin
        xyz="0 0 0"
        rpy="0 0 0" />
      <geometry>
        <mesh
          filename="package://rohand_lites_urdf_ros2/meshes_r/th_slider_link.STL" />
      </geometry>
    </collision>
  </link>
  <joint
    name="th_slider_link"
    type="prismatic">
    <origin
      xyz="-0.0082411 -0.0059277 0.0077"
      rpy="3.1325 0 -2.7163" />
    <parent
      link="th_proximal_link" />
    <child
      link="th_slider_link" />
    <axis
      xyz="1 0 0" />
    <limit
      lower="-0.003"
      upper="0.007"
      effort="0"
      velocity="0" />
  </joint>
  <link
    name="th_connecting_link">
    <inertial>
      <origin
        xyz="-0.00414322253960279 -0.000791734330477717 0.00418010364024101"
        rpy="0 0 0" />
      <mass
        value="0.000246838977263949" />
      <inertia
        ixx="1.39999322829223E-09"
        ixy="-2.2304881806243E-10"
        ixz="3.5967873721528E-14"
        iyy="3.25593360179364E-09"
        iyz="1.8995506521759E-14"
        izz="2.87389464703454E-09" />
    </inertial>
    <visual>
      <origin
        xyz="0 0 0"
        rpy="0 0 0" />
      <geometry>
        <mesh
          filename="package://rohand_lites_urdf_ros2/meshes_r/th_connecting_link.STL" />
      </geometry>
      <material
        name="">
        <color
          rgba="1 1 1 1" />
      </material>
    </visual>
    <collision>
      <origin
        xyz="0 0 0"
        rpy="0 0 0" />
      <geometry>
        <mesh
          filename="package://rohand_lites_urdf_ros2/meshes_r/th_connecting_link.STL" />
      </geometry>
    </collision>
  </link>
  <joint
    name="th_connecting_link"
    type="continuous">
    <origin
      xyz="0.0333 -0.00016876 0.0042837"
      rpy="3.1334 0.0037317 -2.7164" />
    <parent
      link="th_slider_link" />
    <child
      link="th_connecting_link" />
    <axis
      xyz="0 0 1" />
  </joint>
  <link
    name="th_distal_link">
    <inertial>
      <origin
        xyz="-0.0094593690473327 -0.0057218027674614 0.0068108911892128"
        rpy="0 0 0" />
      <mass
        value="0.00464616536496131" />
      <inertia
        ixx="1.70526363877279E-07"
        ixy="-1.70171405060127E-08"
        ixz="-3.06434125828904E-12"
        iyy="2.37897880292055E-07"
        iyz="1.31087369006255E-12"
        izz="2.09937364304614E-07" />
    </inertial>
    <visual>
      <origin
        xyz="0 0 0"
        rpy="0 0 0" />
      <geometry>
        <mesh
          filename="package://rohand_lites_urdf_ros2/meshes_r/th_distal_link.STL" />
      </geometry>
      <material
        name="">
        <color
          rgba="1 1 1 1" />
      </material>
    </visual>
    <collision>
      <origin
        xyz="0 0 0"
        rpy="0 0 0" />
      <geometry>
        <mesh
          filename="package://rohand_lites_urdf_ros2/meshes_r/th_distal_link.STL" />
      </geometry>
    </collision>
  </link>
  <joint
    name="th_distal_link"
    type="continuous">
    <origin
      xyz="-0.048752 -0.010712 0.00087944"
      rpy="0 0 0" />
    <parent
      link="th_proximal_link" />
    <child
      link="th_distal_link" />
    <axis
      xyz="0 0 1" />
  </joint>
</robot>
